Workbook

Sheet Heroes
C1: DEADLOCK HERO BASE STATS/SCALING
L2: TOTAL BOONS | M2: Hero Spirit | O2: TOTAL HEROES
B3: global modifier | L3: 35 | M3: 38 | O3: =counta(Table1[Hero Name]) -> 39 | Y3: DPM = DAMAGE PER MAGAZINE
C4: todo: bullet radius | E4: if you want to use table sorting features, make a copy locally. i can't enable that for viewers without giving editing permissions
A5: Hero Name | B5: Base Bullet Dmg | C5: Pellets | D5: Alt Fire Type/Dmg | E5: Alt Fire Pellets | F5: Base Ammo | G5: Base Fire Rate | H5: Base DPS | I5: DPM | J5: Falloff Range Min | K5: Falloff Range Max | L5: Hero Labs | M5: Base HP | N5: Base Regen | O5: Base Move Speed | P5: Base Sprint | Q5: Base Stamina | R5: ||| | S5: Dmg Gain | T5: HP Gain | U5: Spirit Gain | V5: ||||||| | W5: Max Level HP | X5: Max Gun Damage | Y5: Max Gun DPS | Z5: Max DPM | AA5: dps % growth increase | AB5: hp % growth increase | AC5: aggregate growth % | AD5: |||||||||| | AE5: Spirit Scaling | AF5: Spirit Ratio | AG5: Spirit Bonus | AH5: Spirit Scaling 2 | AI5: Spirit Ratio 2 | AJ5: Spirit Bonus 2 | AK5: Ability 1 Damage | AL5: Ability 2 Damage | AM5: Ability 3 Damage | AN5: Ability 1 Spirit Scaling | AO5: Ability 1 Alt Scaling | AP5: Ability 2 Spirit Scaling | AQ5: Ability 2 Alt Scaling | AR5: Ability 3 Spirit Scaling | AS5: Ability 3 Alt Scaling | AT5: Column 40
A6: Celeste | H6: =B6*C6*G6 -> 0 | I6: =F6*B6*C6 -> 0 | L6: x | M6: 750 | N6: 2 | O6: 6.4 | P6: 1.6 | Q6: 3 | S6: 0.4 | T6: 35 | U6: 1.1 | W6: =T6*$L$3+M6 -> 1975 | X6: =S6*($L$3)+B6 -> 14 | Y6: =X6*G6*C6 -> 0 | Z6: =X6*F6*C6 -> 0 | AA6: =(Y6-H6)/H6 -> #DIV/0! | AB6: =(W6-M6)/M6 -> 1.6333333 | AC6: =AA6+AB6 -> #DIV/0!
A7: Apollo | H7: =B7*C7*G7 -> 0 | I7: =F7*B7*C7 -> 0 | L7: x | M7: 700 | N7: 2 | O7: 7.2 | P7: 1.6 | Q7: 3 | S7: 1.2 | T7: 41 | U7: 1.1 | W7: =T7*$L$3+M7 -> 2135 | X7: =S7*($L$3)+B7 -> 42 | Y7: =X7*G7*C7 -> 0 | Z7: =X7*F7*C7 -> 0 | AA7: =(Y7-H7)/H7 -> #DIV/0! | AB7: =(W7-M7)/M7 -> 2.05 | AC7: =AA7+AB7 -> #DIV/0!
A8: Mina | B8: 7.31 | C8: 1 | D8: zoom | E8: 1 | F8: 12 | G8: 3.97 | H8: =B8*C8*G8 -> 29.0207 | I8: =F8*B8 -> 87.72 | J8: 20 | K8: 46 | M8: 630 | N8: 2 | O8: 7.29 | P8: 2 | Q8: 2 | S8: 0.28 | T8: 28 | U8: 1.1 | W8: =T8*$L$3+M8 -> 1610 | X8: =S8*($L$3)+B8 -> 17.11 | Y8: =X8*G8*C8 -> 67.9267 | Z8: =X8*F8*C8 -> 205.32 | AA8: =(Y8-H8)/H8 -> 1.3406293 | AB8: =(W8-M8)/M8 -> 1.5555556 | AC8: =AA8+AB8 -> 2.8961848
A9: Holliday | B9: 18.8 | C9: 1 | D9: zoom | E9: 1 | F9: 10 | G9: 2.12 | H9: =B9*C9*G9 -> 39.856 | I9: =F9*B9 -> 188 | J9: 20 | K9: 58 | M9: 750 | N9: 1 | O9: 8.3 | P9: 0.5 | Q9: 2 | S9: 1.14 | T9: 41 | U9: 1.1 | W9: =T9*$L$3+M9 -> 2185 | X9: =S9*($L$3)+B9 -> 58.7 | Y9: =X9*G9*C9 -> 124.444 | Z9: =X9*F9 -> 587 | AA9: =(Y9-H9)/H9 -> 2.1223404 | AB9: =(W9-M9)/M9 -> 1.9133333 | AC9: =AA9+AB9 -> 4.0356738
A10: Graves | B10: 4.2 | C10: 1 | D10: zoom | E10: 1 | F10: 40 | G10: 9.8 | H10: =B10*C10*G10 -> 41.16 | I10: =F10*B10*C10 -> 168 | J10: 8 | K10: 18 | L10: x | M10: 700 | N10: 1 | O10: 6.6 | P10: 1.6 | Q10: 2 | S10: 0.06 | T10: 33 | U10: 1.1 | W10: =T10*$L$3+M10 -> 1855 | X10: =S10*($L$3)+B10 -> 6.3 | Y10: =X10*G10*C10 -> 61.74 | Z10: =X10*F10*C10 -> 252 | AA10: =(Y10-H10)/H10 -> 0.5 | AB10: =(W10-M10)/M10 -> 1.65 | AC10: =AA10+AB10 -> 2.15
A11: Mirage | B11: 15.2 | C11: 1 | D11: zoom | E11: 1 | F11: 16 | G11: 2.72 | H11: =B11*C11*G11 -> 41.344 | I11: =F11*B11 -> 243.2 | J11: 20 | K11: 58 | M11: 700 | N11: 2 | O11: 7.3 | P11: 0.5 | Q11: 3 | S11: 0.5 | T11: 44 | U11: 1.1 | W11: =T11*$L$3+M11 -> 2240 | X11: =S11*($L$3)+B11 -> 32.7 | Y11: =X11*G11*C11 -> 88.944 | Z11: =X11*F11 -> 523.2 | AA11: =(Y11-H11)/H11 -> 1.1513158 | AB11: =(W11-M11)/M11 -> 2.2 | AC11: =AA11+AB11 -> 3.3513158
A12: Doorman | B12: 29 | C12: 1 | D12: zoom | E12: 1 | F12: 8 | G12: 1.47 | H12: =B12*C12*G12 -> 42.63 | I12: =F12*B12 -> 232 | J12: 20 | K12: 58 | M12: 725 | N12: 1 | O12: 8 | P12: 2 | Q12: 3 | S12: 1.1 | T12: 42 | U12: 1.1 | W12: =T12*$L$3+M12 -> 2195 | X12: =S12*($L$3)+B12 -> 67.5 | Y12: =X12*G12*C12 -> 99.225 | Z12: =X12*F12*C12 -> 540 | AA12: =(Y12-H12)/H12 -> 1.3275862 | AB12: =(W12-M12)/M12 -> 2.0275862 | AC12: =AA12+AB12 -> 3.3551724
A13: Silver | B13: 5.5 | C13: 7 | D13: zoom | E13: 7 | F13: 5 | G13: 1.11 | H13: =B13*C13*G13 -> 42.735 | I13: =F13*B13*C13 -> 192.5 | J13: 16 | K13: 46 | L13: x | M13: 725 | N13: 2 | O13: 6.7 | P13: 1.5 | Q13: 2 | S13: 0.12 | T13: 29 | U13: 1.1 | W13: =T13*$L$3+M13 -> 1740 | X13: =S13*($L$3)+B13 -> 9.7 | Y13: =X13*G13*C13 -> 75.369 | Z13: =X13*F13*C13 -> 339.5 | AA13: =(Y13-H13)/H13 -> 0.76363636 | AB13: =(W13-M13)/M13 -> 1.4 | AC13: =AA13+AB13 -> 2.1636364
A14: Drifter | B14: 19.5 | C14: 1 | D14: zoom | E14: 1 | F14: 12 | G14: 2.27 | H14: =B14*C14*G14 -> 44.265 | I14: =F14*B14*C14 -> 234 | J14: 20 | K14: 46 | M14: 725 | N14: 3.5 | O14: 7.01 | P14: 2 | Q14: 3 | S14: 0.62 | T14: 39 | U14: 1.1 | W14: =T14*$L$3+M14 -> 2090 | X14: =S14*($L$3)+B14 -> 41.2 | Y14: =X14*G14*C14 -> 93.524 | Z14: =X14*F14*C14 -> 494.4 | AA14: =(Y14-H14)/H14 -> 1.1128205 | AB14: =(W14-M14)/M14 -> 1.8827586 | AC14: =AA14+AB14 -> 2.9955791
A15: Dynamo | B15: 12.2 | C15: 1 | D15: zoom | E15: 1 | F15: 18 | G15: 3.81 | H15: =B15*C15*G15 -> 46.482 | I15: =F15*B15 -> 219.6 | J15: 20 | K15: 58 | M15: 850 | N15: 2.5 | O15: 6.8 | P15: 0.5 | Q15: 3 | S15: 0.44 | T15: 59 | U15: 1.1 | W15: =T15*$L$3+M15 -> 2915 | X15: =S15*($L$3)+B15 -> 27.6 | Y15: =X15*G15*C15 -> 105.156 | Z15: =X15*F15 -> 496.8 | AA15: =(Y15-H15)/H15 -> 1.2622951 | AB15: =(W15-M15)/M15 -> 2.4294118 | AC15: =AA15+AB15 -> 3.6917068
A16: Lady Geist | B16: 22 | C16: 1 | D16: zoom | E16: 1 | F16: 10 | G16: 2.12 | H16: =B16*C16*G16 -> 46.64 | I16: =F16*B16 -> 220 | J16: 20 | K16: 58 | M16: 850 | N16: 1 | O16: 6.3 | P16: 1.5 | Q16: 3 | S16: 0.95 | T16: 51 | U16: 1.1 | W16: =T16*$L$3+M16 -> 2635 | X16: =S16*($L$3)+B16 -> 55.25 | Y16: =X16*G16*C16 -> 117.13 | Z16: =X16*F16 -> 552.5 | AA16: =(Y16-H16)/H16 -> 1.5113636 | AB16: =(W16-M16)/M16 -> 2.1 | AC16: =AA16+AB16 -> 3.6113636
A17: Grey Talon | B17: =24+AG17 -> 27.04 | C17: 1 | D17: zoom | E17: 1 | F17: 17 | G17: 1.73 | H17: =B17*C17*G17 -> 46.7792 | I17: =F17*B17 -> 459.68 | J17: 18 | K17: 54 | M17: 750 | N17: 2 | O17: 6.3 | P17: 0.5 | Q17: 3 | S17: 1 | T17: 38 | U17: 1.1 | W17: =T17*$L$3+M17 -> 2080 | X17: =(S17*$L$3)+B17 -> 62.04 | Y17: =X17*G17*C17 -> 107.3292 | Z17: =X17*F17 -> 1054.68 | AA17: =(Y17-H17)/H17 -> 1.2943787 | AB17: =(W17-M17)/M17 -> 1.7733333 | AC17: =AA17+AB17 -> 3.067712 | AE17: base damage | AF17: 0.08 | AG17: =AF17*$M$3 -> 3.04 | AH17: movement speed | AI17: 0.034 | AJ17: =AI17*$M$3 -> 1.292
A18: Sinclair | B18: 17.8 | C18: 1 | D18: zoom | E18: 1 | F18: 20 | G18: 2.72 | H18: =B18*C18*G18 -> 48.416 | I18: =F18*B18 -> 356 | J18: 25 | K18: 61 | M18: 700 | N18: 2 | O18: 7.6 | P18: 0.5 | Q18: 3 | S18: 0.55 | T18: 38 | U18: 1.1 | W18: =T18*$L$3+M18 -> 2030 | X18: =S18*($L$3)+B18 -> 37.05 | Y18: =X18*G18*C18 -> 100.776 | Z18: =X18*F18 -> 741 | AA18: =(Y18-H18)/H18 -> 1.0814607 | AB18: =(W18-M18)/M18 -> 1.9 | AC18: =AA18+AB18 -> 2.9814607 | AE18: movement speed | AF18: 0.023
A19: Paradox | B19: 6.42 | C19: 1 | D19: zoom | E19: 1 | F19: 40 | G19: 7.56 | H19: =B19*C19*G19 -> 48.5352 | I19: =F19*B19 -> 256.8 | J19: 20 | K19: 58 | M19: 700 | N19: 1 | O19: 6.8 | P19: 0.5 | Q19: 3 | S19: 0.24 | T19: 45 | U19: 1.1 | W19: =T19*$L$3+M19 -> 2275 | X19: =S19*($L$3)+B19 -> 14.82 | Y19: =X19*G19*C19 -> 112.0392 | Z19: =X19*F19 -> 592.8 | AA19: =(Y19-H19)/H19 -> 1.3084112 | AB19: =(W19-M19)/M19 -> 2.25 | AC19: =AA19+AB19 -> 3.5584112
A20: Viscous | B20: 10.3 | C20: 1 | D20: 42 | E20: 1 | F20: 24 | G20: 4.76 | H20: =B20*C20*G20 -> 49.028 | I20: =F20*B20 -> 247.2 | J20: 20 | K20: 58 | M20: 750 | N20: 2 | O20: 7.3 | P20: 0.5 | Q20: 3 | S20: 0.36 | T20: 44 | U20: 1.3 | W20: =T20*$L$3+M20 -> 2290 | X20: =S20*($L$3)+B20 -> 22.9 | Y20: =X20*G20*C20 -> 109.004 | Z20: =X20*F20 -> 549.6 | AA20: =(Y20-H20)/H20 -> 1.223301 | AB20: =(W20-M20)/M20 -> 2.0533333 | AC20: =AA20+AB20 -> 3.2766343
A21: Lash | B21: 8.46 | C21: 1 | D21: zoom | E21: 1 | F21: 29 | G21: 5.83 | H21: =B21*C21*G21 -> 49.3218 | I21: =F21*B21 -> 245.34 | J21: 20 | K21: 58 | M21: 750 | N21: 2 | O21: 7.3 | P21: 1.5 | Q21: 3 | S21: 0.34 | T21: 50 | U21: 1.1 | W21: =T21*$L$3+M21 -> 2500 | X21: =S21*($L$3)+B21 -> 20.36 | Y21: =X21*G21*C21 -> 118.6988 | Z21: =X21*F21 -> 590.44 | AA21: =(Y21-H21)/H21 -> 1.4066194 | AB21: =(W21-M21)/M21 -> 2.3333333 | AC21: =AA21+AB21 -> 3.7399527
A22: Haze | B22: 5.26 | C22: 1 | D22: zoom | E22: 1 | F22: =25+AG22 -> 44 | G22: 9.52 | H22: =B22*C22*G22 -> 50.0752 | I22: =F22*B22 -> 231.44 | J22: 20 | K22: 46 | M22: 700 | N22: 2 | O22: 8.3 | P22: 0.5 | Q22: 3 | S22: 0.14 | T22: 33 | U22: 1.1 | W22: =T22*$L$3+M22 -> 1855 | X22: =S22*($L$3)+B22+AJ22 -> 10.16 | Y22: =X22*G22*C22 -> 96.7232 | Z22: =X22*F22 -> 447.04 | AA22: =(Y22-H22)/H22 -> 0.93155894 | AB22: =(W22-M22)/M22 -> 1.65 | AC22: =AA22+AB22 -> 2.5815589 | AE22: ammo (base) | AF22: 0.5 | AG22: =AF22*$M$3 -> 19 | AH22: base damage | AI22: 0.025
A23: Shiv | B23: 4.8 | C23: 6 | D23: 4.6 | E23: 12 | F23: 10 | G23: 1.81 | H23: =B23*C23*G23 -> 52.128 | I23: =F23*C23*B23 -> 288 | J23: 20 | K23: 41 | M23: 800 | N23: 2 | O23: 7 | P23: 0.5 | Q23: 3 | S23: 0.14 | T23: 48 | U23: 1.1 | W23: =T23*$L$3+M23 -> 2480 | X23: =S23*($L$3)+B23 -> 9.7 | Y23: =X23*G23*C23 -> 105.342 | Z23: =X23*F23*C23 -> 582 | AA23: =(Y23-H23)/H23 -> 1.0208333 | AB23: =(W23-M23)/M23 -> 2.1 | AC23: =AA23+AB23 -> 3.1208333
A24: Infernus | B24: 5.5 | C24: 1 | D24: zoom | E24: 1 | F24: 27 | G24: 9.52 | H24: =B24*C24*G24 -> 52.36 | I24: =F24*B24 -> 148.5 | J24: 20 | K24: 58 | M24: 800 | N24: 2 | O24: 6.8 | P24: 0.5 | Q24: 3 | S24: 0.09 | T24: 39 | U24: 1.1 | W24: =T24*$L$3+M24 -> 2165 | X24: =S24*($L$3)+B24 -> 8.65 | Y24: =X24*G24*C24 -> 82.348 | Z24: =X24*F24 -> 233.55 | AA24: =(Y24-H24)/H24 -> 0.57272727 | AB24: =(W24-M24)/M24 -> 1.70625 | AC24: =AA24+AB24 -> 2.2789773
A25: Abrams | B25: 3.86 | C25: 9 | D25: zoom | E25: 9 | F25: 9 | G25: 1.59 | H25: =B25*C25*G25 -> 55.2366 | I25: =F25*C25*B25 -> 312.66 | J25: 20 | K25: 46 | M25: 770 | N25: 1 | O25: 6.8 | P25: 0.5 | Q25: 3 | S25: 0.13 | T25: 49 | U25: 1.1 | W25: =T25*$L$3+M25 -> 2485 | X25: =S25*($L$3)+B25 -> 8.41 | Y25: =X25*G25*C25 -> 120.3471 | Z25: =X25*F25*C25 -> 681.21 | AA25: =(Y25-H25)/H25 -> 1.1787565 | AB25: =(W25-M25)/M25 -> 2.2272727 | AC25: =AA25+AB25 -> 3.4060292
A26: Vindicta | B26: 12.3 | C26: 1 | D26: zoom | E26: 1 | F26: 22 | G26: =4.33+(4*AG26%) -> 4.5428 | H26: =B26*C26*G26 -> 55.87644 | I26: =F26*B26 -> 270.6 | J26: 20 | K26: 64 | M26: 725 | N26: 2 | O26: 9 | P26: 0.5 | Q26: 2 | S26: 0.5 | T26: 29 | U26: 1.1 | W26: =T26*$L$3+M26 -> 1740 | X26: =S26*($L$3)+B26 -> 29.8 | Y26: =X26*G26*C26 -> 135.37544 | Z26: =X26*F26 -> 655.6 | AA26: =(Y26-H26)/H26 -> 1.4227642 | AB26: =(W26-M26)/M26 -> 1.4 | AC26: =AA26+AB26 -> 2.8227642 | AE26: fire rate | AF26: 0.14 | AG26: =AF26*$M$3 -> 5.32
A27: Pocket | B27: 4.28 | C27: 7 | D27: zoom | E27: 7 | F27: 11 | G27: 1.91 | H27: =B27*C27*G27 -> 57.2236 | I27: =F27*C27*B27 -> 329.56 | J27: 16 | K27: 46 | M27: 750 | N27: 1 | O27: 7.3 | P27: 0.5 | Q27: 3 | S27: 0.22 | T27: 36 | U27: 1.1 | W27: =T27*$L$3+M27 -> 2010 | X27: =S27*($L$3)+B27 -> 11.98 | Y27: =X27*G27*C27 -> 160.1726 | Z27: =X27*F27*C27 -> 922.46 | AA27: =(Y27-H27)/H27 -> 1.7990654 | AB27: =(W27-M27)/M27 -> 1.68 | AC27: =AA27+AB27 -> 3.4790654
A28: Paige | B28: 35 | C28: 1 | D28: zoom | E28: 1 | F28: 9 | G28: 1.67 | H28: =B28*C28*G28 -> 58.45 | I28: =F28*B28 -> 315 | J28: 20 | K28: 58 | M28: 650 | N28: 2 | O28: 7.01 | P28: 4 | Q28: 2 | S28: 0.52 | T28: 29 | U28: 1.1 | W28: =T28*$L$3+M28 -> 1665 | X28: =S28*($L$3)+B28 -> 53.2 | Y28: =X28*G28*C28 -> 88.844 | Z28: =X28*F28*C28 -> 478.8 | AA28: =(Y28-H28)/H28 -> 0.52 | AB28: =(W28-M28)/M28 -> 1.5615385 | AC28: =AA28+AB28 -> 2.0815385
A29: Bebop | B29: 4.98 | C29: 1 | D29: windup | E29: 1 | F29: 66 | G29: 11.9 | H29: =B29*C29*G29 -> 59.262 | I29: =F29*B29 -> 328.68 | J29: 20 | K29: 51 | M29: 850 | N29: 1.5 | O29: 6.6 | P29: 3.5 | Q29: 3 | S29: 0.15 | T29: 46 | U29: 1.1 | W29: =T29*$L$3+M29 -> 2460 | X29: =S29*($L$3)+B29 -> 10.23 | Y29: =X29*G29*C29 -> 121.737 | Z29: =X29*F29 -> 675.18 | AA29: =(Y29-H29)/H29 -> 1.0542169 | AB29: =(W29-M29)/M29 -> 1.8941176 | AC29: =AA29+AB29 -> 2.9483345
A30: Mo & Krill | B30: 2.82 | C30: 4 | D30: zoom | E30: 4 | F30: 20 | G30: 5.29 | H30: =B30*C30*G30 -> 59.6712 | I30: =F30*B30*C30 -> 225.6 | J30: 20 | K30: 58 | M30: 900 | N30: 1 | O30: 8.1 | P30: 0.5 | Q30: 3 | S30: 0.08 | T30: 63 | U30: 1.1 | W30: =T30*$L$3+M30 -> 3105 | X30: =S30*($L$3)+B30 -> 5.62 | Y30: =X30*G30*C30 -> 118.9192 | Z30: =X30*F30*C30 -> 449.6 | AA30: =(Y30-H30)/H30 -> 0.9929078 | AB30: =(W30-M30)/M30 -> 2.45 | AC30: =AA30+AB30 -> 3.4429078
A31: Wraith | B31: 5.64 | C31: 1 | D31: zoom | E31: 1 | F31: 52 | G31: 10.6 | H31: =B31*C31*G31 -> 59.784 | I31: =F31*B31 -> 293.28 | J31: 18 | K31: 52 | M31: 700 | N31: 2 | O31: 7.3 | P31: =0.5+AG31 -> 2.78 | Q31: 3 | S31: 0.14 | T31: 35 | U31: 1.1 | W31: =T31*$L$3+M31 -> 1925 | X31: =S31*($L$3)+B31 -> 10.54 | Y31: =X31*G31*C31 -> 111.724 | Z31: =X31*F31 -> 548.08 | AA31: =(Y31-H31)/H31 -> 0.86879433 | AB31: =(W31-M31)/M31 -> 1.75 | AC31: =AA31+AB31 -> 2.6187943 | AE31: sprint speed | AF31: 0.06 | AG31: =AF31*$M$3 -> 2.28
A32: REM | B32: 16 | C32: 1 | D32: zoom | E32: 1 | F32: 13 | G32: 3.85 | H32: =B32*C32*G32 -> 61.6 | I32: =F32*B32*C32 -> 208 | J32: 20 | K32: 58 | M32: 650 | N32: 2 | O32: 7.2 | P32: 4 | Q32: 3 | S32: 0.34 | T32: 29 | U32: 1.1 | W32: =T32*$L$3+M32 -> 1665 | X32: =S32*($L$3)+B32 -> 27.9 | Y32: =X32*G32*C32 -> 107.415 | Z32: =X32*F32*C32 -> 362.7 | AA32: =(Y32-H32)/H32 -> 0.74375 | AB32: =(W32-M32)/M32 -> 1.5615385 | AC32: =AA32+AB32 -> 2.3052885
A33: Ivy | B33: 4.59 | C33: 1 | D33: zoom | E33: 1 | F33: 33 | G33: 13.6 | H33: =B33*C33*G33 -> 62.424 | I33: =F33*B33 -> 151.47 | J33: 20 | K33: 58 | M33: 725 | N33: 2 | O33: 7.3 | P33: 0.5 | Q33: 4 | S33: 0.12 | T33: 44 | U33: 1.2 | W33: =T33*$L$3+M33 -> 2265 | X33: =S33*($L$3)+B33 -> 8.79 | Y33: =X33*G33*C33 -> 119.544 | Z33: =X33*F33 -> 290.07 | AA33: =(Y33-H33)/H33 -> 0.91503268 | AB33: =(W33-M33)/M33 -> 2.1241379 | AC33: =AA33+AB33 -> 3.0391706
A34: Seven | B34: 10.8 | C34: 1 | D34: zoom | E34: 1 | F34: 29 | G34: 5.83 | H34: =B34*C34*G34 -> 62.964 | I34: =F34*B34 -> 313.2 | J34: 20 | K34: 58 | M34: 700 | N34: 1 | O34: 6.8 | P34: 0.5 | Q34: 3 | S34: 0.37 | T34: 41 | U34: 1.1 | W34: =T34*$L$3+M34 -> 2135 | X34: =S34*($L$3)+B34 -> 23.75 | Y34: =X34*G34*C34 -> 138.4625 | Z34: =X34*F34 -> 688.75 | AA34: =(Y34-H34)/H34 -> 1.1990741 | AB34: =(W34-M34)/M34 -> 2.05 | AC34: =AA34+AB34 -> 3.2490741 | AE34: movement speed | AF34: 0.023 | AG34: =AF34*$M$3 -> 0.874
A35: Yamato | B35: 5.31 | C35: 5 | D35: 50 | E35: 1 | F35: 12 | G35: 2.38 | H35: =B35*C35*G35 -> 63.189 | I35: =F35*B35*C35 -> 318.6 | J35: 20 | K35: 46 | M35: 700 | N35: 1 | O35: 8.3 | P35: 0.5 | Q35: 3 | S35: 0.15 | T35: 44 | U35: 1.1 | W35: =T35*$L$3+M35 -> 2240 | X35: =S35*($L$3)+B35 -> 10.56 | Y35: =X35*G35*C35 -> 125.664 | Z35: =X35*F35*C35 -> 633.6 | AA35: =(Y35-H35)/H35 -> 0.98870057 | AB35: =(W35-M35)/M35 -> 2.2 | AC35: =AA35+AB35 -> 3.1887006 | AE35: ammo (base) | AF35: 0.15 | AG35: =AF35*$M$3 -> 5.7
A36: Venator | B36: 8 | C36: 1 | D36: zoom | E36: 1 | F36: 33 | G36: 7.94 | H36: =B36*C36*G36 -> 63.52 | I36: =F36*B36*C36 -> 264 | J36: 20 | K36: 51 | L36: x | M36: 720 | N36: 2 | O36: 6.4 | P36: 1.5 | Q36: 3 | S36: 0.27 | T36: 38 | U36: 1.1 | W36: =T36*$L$3+M36 -> 2050 | X36: =S36*($L$3)+B36 -> 17.45 | Y36: =X36*G36*C36 -> 138.553 | Z36: =X36*F36*C36 -> 575.85 | AA36: =(Y36-H36)/H36 -> 1.18125 | AB36: =(W36-M36)/M36 -> 1.8472222 | AC36: =AA36+AB36 -> 3.0284722
A37: Victor | B37: 12 | C37: 1 | D37: zoom | E37: 1 | F37: 24 | G37: 5.85 | H37: =B37*C37*G37 -> 70.2 | I37: =F37*B37 -> 288 | J37: 20 | K37: 58 | M37: 770 | N37: 1.5 | O37: 6.3 | P37: 1.5 | Q37: 3 | S37: 0.33 | T37: 39 | U37: 1.1 | W37: =T37*$L$3+M37 -> 2135 | X37: =S37*($L$3)+B37 -> 23.55 | Y37: =X37*G37*C37 -> 137.7675 | Z37: =X37*F37*C37 -> 565.2 | AA37: =(Y37-H37)/H37 -> 0.9625 | AB37: =(W37-M37)/M37 -> 1.7727273 | AC37: =AA37+AB37 -> 2.7352273
A38: Kelvin | B38: 18.6 | C38: 1 | D38: zoom | E38: 1 | F38: 14 | G38: 3.81 | H38: =B38*C38*G38 -> 70.866 | I38: =F38*B38 -> 260.4 | J38: 20 | K38: 58 | M38: 850 | N38: 1 | O38: 6.8 | P38: 0.5 | Q38: 3 | S38: 0.42 | T38: 58 | U38: 1.3 | W38: =T38*$L$3+M38 -> 2880 | X38: =S38*($L$3)+B38 -> 33.3 | Y38: =X38*G38*C38 -> 126.873 | Z38: =X38*F38 -> 466.2 | AA38: =(Y38-H38)/H38 -> 0.79032258 | AB38: =(W38-M38)/M38 -> 2.3882353 | AC38: =AA38+AB38 -> 3.1785579
A39: Priest | B39: 8 | C39: 1 | D39: zoom | E39: 1 | F39: 30 | G39: 7.94 | H39: =B39*C39*G39 -> 63.52 | I39: =F39*B39 -> 240 | J39: 20 | K39: 58 | L39: E | M39: 700 | N39: 2 | O39: 6.5 | P39: 2 | Q39: 3 | S39: 0.32 | T39: 37 | W39: =T39*$L$3+M39 -> 1995 | X39: =S39*($L$3)+B39 -> 19.2 | Y39: =X39*G39*C39 -> 152.448 | Z39: =X39*F39*C39 -> 576
A40: Warden | B40: 17.3 | C40: 1 | D40: zoom | E40: 1 | F40: 17 | G40: =3.81+(4*AG40%) -> 4.19 | H40: =B40*C40*G40 -> 72.487 | I40: =F40*B40 -> 294.1 | J40: 20 | K40: 58 | M40: 775 | N40: 3 | O40: 6.3 | P40: 2 | Q40: 3 | S40: 0.47 | T40: 58 | U40: 1.1 | W40: =T40*$L$3+M40 -> 2805 | X40: =S40*($L$3)+B40 -> 33.75 | Y40: =X40*G40*C40 -> 141.4125 | Z40: =X40*F40 -> 573.75 | AA40: =(Y40-H40)/H40 -> 0.95086705 | AB40: =(W40-M40)/M40 -> 2.6193548 | AC40: =AA40+AB40 -> 3.5702219 | AE40: fire rate | AF40: 0.25 | AG40: =AF40*$M$3 -> 9.5
...

Sheet damage calculator
A1: BULLET DMG | E1: shred 1 | F1: 0.13 | H1: Enemy Res | I1: 0.5 | Q1: extended dmg info | S1: inc amount % | T1: weapon damage | U1: fire rate | V1: shred | W1: lucky shot?
A2: Hero | B2: Warden | C2: Damage | D2: =VLOOKUP(B2, Heroes!$A$6:$H$48, 2, FALSE) -> 17.3 | E2: shred 2 | F2: 0 | H2: dmg shred or firerate? | M2: Damage Growth | O2: =VLOOKUP(B2, Heroes!$A$6:$S$48, 19, FALSE)*B3 -> 14.1 | Q2: this uses values | S2: 1 | T2: =($D$8+(($O$3*(S2/100))*$N$7))*($F$8*-1)+($D$8+(($O$3*(S2/100))*$N$7)) -> 83.715446 | U2: =($N$7*(1+S2/100)*$N$6)*($F$8*-1)+($N$7*(1+S2/100)*$N$6) -> 83.715446 | V2: =$D$8*(($F$8-S2/100)*-1)+$D$8 -> 84.20224 | W2: =(N6+N6*1.25)*(F8*-1)+(N6+N6*1.25) -> 44.5095
A3: Boons | B3: 30 | C3: Pellets | D3: =VLOOKUP(B2, Heroes!$A$6:$H$48, 3, FALSE) -> 1 | E3: shred 3 | F3: 0 | M3: Total Damage | O3: =O2+D2 -> 31.4 | Q3: from the left | S3: 2 | T3: =($D$8+(($O$3*(S3/100))*$N$7))*($F$8*-1)+($D$8+(($O$3*(S3/100))*$N$7)) -> 84.544312 | U3: =($N$7*(1+S3/100)*$N$6)*($F$8*-1)+($N$7*(1+S3/100)*$N$6) -> 84.544312 | V3: =$D$8*(($F$8-S3/100)*-1)+$D$8 -> 85.5179 | W3: lucky dps inc
C4: Bullets Per Sec | D4: =VLOOKUP(B2, Heroes!$A$6:$H$48, 7, FALSE) -> 4.19 | E4: shred 4 | F4: 0 | H4: 10% shred | I4: 20% wpn dmg | J4: 10% fire rate | S4: 3 | T4: =($D$8+(($O$3*(S4/100))*$N$7))*($F$8*-1)+($D$8+(($O$3*(S4/100))*$N$7)) -> 85.373177 | U4: =($N$7*(1+S4/100)*$N$6)*($F$8*-1)+($N$7*(1+S4/100)*$N$6) -> 85.373177 | V4: =$D$8*(($F$8-S4/100)*-1)+$D$8 -> 86.83356 | W4: =W2/4 -> 11.127375
A5: mag size | B5: =VLOOKUP(B2, Heroes!$A$6:$H$48, 6, FALSE) -> 17 | E5: shred 5 | F5: 0 | H5: =D8*((F8-0.1)*-1)+D8 -> 96.04318 | I5: =(D8+((O3*0.2)*N7))*(F8*-1)+(D8+((O3*0.2)*N7)) -> 99.463896 | J5: =(N7*1.1*N6)*(F8*-1)+(N7*1.1*N6) -> 91.175238 | S5: 4 | T5: =($D$8+(($O$3*(S5/100))*$N$7))*($F$8*-1)+($D$8+(($O$3*(S5/100))*$N$7)) -> 86.202043 | U5: =($N$7*(1+S5/100)*$N$6)*($F$8*-1)+($N$7*(1+S5/100)*$N$6) -> 86.202043 | V5: =$D$8*(($F$8-S5/100)*-1)+$D$8 -> 88.14922 | W5: =W4+G10 -> 94.013955
A6: increased ammo | B6: 1 | C6: Weapon Damage | D6: 0 | E6: total shred | F6: =1-(1-F1)*(1-F2)*(1-F3)*(1-F4)*(1-F5) -> 0.13 | M6: DPB | N6: =O3*(1+D6) -> 31.4 | S6: 5 | T6: =($D$8+(($O$3*(S6/100))*$N$7))*($F$8*-1)+($D$8+(($O$3*(S6/100))*$N$7)) -> 87.030909 | U6: =($N$7*(1+S6/100)*$N$6)*($F$8*-1)+($N$7*(1+S6/100)*$N$6) -> 87.030909 | V6: =$D$8*(($F$8-S6/100)*-1)+$D$8 -> 89.46488 | W6: merc mag %
A7: final magsize | B7: =B5+(B5*B6) -> 34 | C7: Fire Rate | D7: 0 | H7: magdump time | J7: =B7/N7 -> 8.1145585 | M7: BPS | N7: =D4*(1+D7) -> 4.19 | S7: 6 | T7: =($D$8+(($O$3*(S7/100))*$N$7))*($F$8*-1)+($D$8+(($O$3*(S7/100))*$N$7)) -> 87.859775 | U7: =($N$7*(1+S7/100)*$N$6)*($F$8*-1)+($N$7*(1+S7/100)*$N$6) -> 87.859775 | V7: =$D$8*(($F$8-S7/100)*-1)+$D$8 -> 90.78054 | W7: 0.68
C8: Modified DPS | D8: =N8 -> 131.566 | E8: final resist | F8: =I1-F6 -> 0.37 | M8: Total DPS | N8: =N6*N7 -> 131.566 | S8: 7 | T8: =($D$8+(($O$3*(S8/100))*$N$7))*($F$8*-1)+($D$8+(($O$3*(S8/100))*$N$7)) -> 88.688641 | U8: =($N$7*(1+S8/100)*$N$6)*($F$8*-1)+($N$7*(1+S8/100)*$N$6) -> 88.688641 | V8: =$D$8*(($F$8-S8/100)*-1)+$D$8 -> 92.0962 | W8: merc dmg
S9: 8 | T9: =($D$8+(($O$3*(S9/100))*$N$7))*($F$8*-1)+($D$8+(($O$3*(S9/100))*$N$7)) -> 89.517506 | U9: =($N$7*(1+S9/100)*$N$6)*($F$8*-1)+($N$7*(1+S9/100)*$N$6) -> 89.517506 | V9: =$D$8*(($F$8-S9/100)*-1)+$D$8 -> 93.41186 | W9: =O3*W7 -> 21.352
F10: Final DPS | G10: =D8*(F8*-1)+D8 -> 82.88658 | S10: 9 | T10: =($D$8+(($O$3*(S10/100))*$N$7))*($F$8*-1)+($D$8+(($O$3*(S10/100))*$N$7)) -> 90.346372 | U10: =($N$7*(1+S10/100)*$N$6)*($F$8*-1)+($N$7*(1+S10/100)*$N$6) -> 90.346372 | V10: =$D$8*(($F$8-S10/100)*-1)+$D$8 -> 94.72752 | W10: merc dps inc
S11: 10 | T11: =($D$8+(($O$3*(S11/100))*$N$7))*($F$8*-1)+($D$8+(($O$3*(S11/100))*$N$7)) -> 91.175238 | U11: =($N$7*(1+S11/100)*$N$6)*($F$8*-1)+($N$7*(1+S11/100)*$N$6) -> 91.175238 | V11: =$D$8*(($F$8-S11/100)*-1)+$D$8 -> 96.04318 | W11: =W9*N7 -> 89.46488
A12: SPIRIT DMG | I12: Enemy Resist | J12: 0.15 | K12: Spirit Strike | L12: 0 | M12: Modified Spirit Multi 1 | O12: =(1-(J12-J13))*B15+J14 -> 0.765 | S12: 11 | T12: =($D$8+(($O$3*(S12/100))*$N$7))*($F$8*-1)+($D$8+(($O$3*(S12/100))*$N$7)) -> 92.004104 | U12: =($N$7*(1+S12/100)*$N$6)*($F$8*-1)+($N$7*(1+S12/100)*$N$6) -> 92.004104 | V12: =$D$8*(($F$8-S12/100)*-1)+$D$8 -> 97.35884 | W12: =W11+G10 -> 172.35146
A13: Ability 1 | C13: Ability 2 | E13: Ability 3 | G13: Ultimate | I13: Resist Shred | J13: =1-(1-L12)*(1-L13)*(1-L14)*(1-L15)*(1-L16)*(1-L17)*(1-L18) -> 0 | K13: Mystic Vuln | L13: 0 | M13: Modified Dmg+Spirit 1 | O13: =O12*B17 -> 47.43 | S13: 12 | T13: =($D$8+(($O$3*(S13/100))*$N$7))*($F$8*-1)+($D$8+(($O$3*(S13/100))*$N$7)) -> 92.83297 | U13: =($N$7*(1+S13/100)*$N$6)*($F$8*-1)+($N$7*(1+S13/100)*$N$6) -> 92.83297 | V13: =$D$8*(($F$8-S13/100)*-1)+$D$8 -> 98.6745
A14: Base Damage | B14: 90 | C14: Base Damage | D14: 190 | E14: Base Damage | F14: 15 | G14: Base Damage | H14: 0 | I14: Spirit Amp | J14: =(L21*0.05) -> 0 | K14: EE | L14: 0 | S14: 13 | T14: =($D$8+(($O$3*(S14/100))*$N$7))*($F$8*-1)+($D$8+(($O$3*(S14/100))*$N$7)) -> 93.661835 | U14: =($N$7*(1+S14/100)*$N$6)*($F$8*-1)+($N$7*(1+S14/100)*$N$6) -> 93.661835 | V14: =$D$8*(($F$8-S14/100)*-1)+$D$8 -> 99.99016
A15: Spirit Multiplier | B15: 0.9 | C15: Spirit Multiplier | D15: 1.7 | E15: Spirit Multiplier | F15: 0.6 | G15: Spirit Multiplier | H15: 0 | K15: Crippling | L15: 0 | M15: Modified Spirit Multi 2 | O15: =(1-(J12-J13))*D15+J14 -> 1.445 | S15: 14 | T15: =($D$8+(($O$3*(S15/100))*$N$7))*($F$8*-1)+($D$8+(($O$3*(S15/100))*$N$7)) -> 94.490701 | U15: =($N$7*(1+S15/100)*$N$6)*($F$8*-1)+($N$7*(1+S15/100)*$N$6) -> 94.490701 | V15: =$D$8*(($F$8-S15/100)*-1)+$D$8 -> 101.30582
K16: Soulshredder | L16: 0 | M16: Modified Dmg+Spirit 2 | O16: =O15*D17 -> 89.59 | S16: 15 | T16: =($D$8+(($O$3*(S16/100))*$N$7))*($F$8*-1)+($D$8+(($O$3*(S16/100))*$N$7)) -> 95.319567 | U16: =($N$7*(1+S16/100)*$N$6)*($F$8*-1)+($N$7*(1+S16/100)*$N$6) -> 95.319567 | V16: =$D$8*(($F$8-S16/100)*-1)+$D$8 -> 102.62148
A17: Current Spirit | B17: 62 | C17: Current Spirit | D17: =B17 -> 62 | E17: Current Spirit | F17: =D17 -> 62 | G17: Current Spirit | H17: =F17 -> 62 | K17: Snatch | L17: 0 | S17: 16 | T17: =($D$8+(($O$3*(S17/100))*$N$7))*($F$8*-1)+($D$8+(($O$3*(S17/100))*$N$7)) -> 96.148433 | U17: =($N$7*(1+S17/100)*$N$6)*($F$8*-1)+($N$7*(1+S17/100)*$N$6) -> 96.148433 | V17: =$D$8*(($F$8-S17/100)*-1)+$D$8 -> 103.93714
A18: Damage+Spirit | B18: =B15*B17 -> 55.8 | C18: Damage+Spirit | D18: =D15*D17 -> 105.4 | E18: Damage+Spirit | F18: =F15*F17 -> 37.2 | G18: Damage+Spirit | H18: =H15*H17 -> 0 | I18: Dmg Per Spirit | K18: Spirit Sap | L18: 0 | M18: Modified Spirit Multi 3 | O18: =(1-(J12-J13))*F15+J14 -> 0.51 | S18: 17 | T18: =($D$8+(($O$3*(S18/100))*$N$7))*($F$8*-1)+($D$8+(($O$3*(S18/100))*$N$7)) -> 96.977299 | U18: =($N$7*(1+S18/100)*$N$6)*($F$8*-1)+($N$7*(1+S18/100)*$N$6) -> 96.977299 | V18: =$D$8*(($F$8-S18/100)*-1)+$D$8 -> 105.2528
A19: Raw Damage | B19: =B17*B15+B14 -> 145.8 | C19: Raw Damage | D19: =D17*D15+D14 -> 295.4 | E19: Raw Damage | F19: =F17*F15+F14 -> 52.2 | G19: Raw Damage | H19: =H17*H15+H14 -> 0 | I19: =O12+O15+O18+O22 -> 2.72 | M19: Modified Dmg+Spirit 3 | O19: =O18*F14 -> 7.65 | S19: 18 | T19: =($D$8+(($O$3*(S19/100))*$N$7))*($F$8*-1)+($D$8+(($O$3*(S19/100))*$N$7)) -> 97.806164 | U19: =($N$7*(1+S19/100)*$N$6)*($F$8*-1)+($N$7*(1+S19/100)*$N$6) -> 97.806164 | V19: =$D$8*(($F$8-S19/100)*-1)+$D$8 -> 106.56846
A20: Modified Damage | C20: Modified Damage | E20: Modified Damage | G20: Modified Damage | I20: Dmg Per Spirit w/ Items | S20: 19 | T20: =($D$8+(($O$3*(S20/100))*$N$7))*($F$8*-1)+($D$8+(($O$3*(S20/100))*$N$7)) -> 98.63503 | U20: =($N$7*(1+S20/100)*$N$6)*($F$8*-1)+($N$7*(1+S20/100)*$N$6) -> 98.63503 | V20: =$D$8*(($F$8-S20/100)*-1)+$D$8 -> 107.88412
B21: =(B19*(1+J14)*(1-(J12-J13))) -> 123.93 | D21: =(D19*(1+J14)*(1-(J12-J13))) -> 251.09 | F21: =(F19*(1+J14)*(1-(J12-J13))) -> 44.37 | H21: =(H19*(1+J14)*(1-(J12+J13))) -> 0 | I21: =I19+1.5+1+0.5 -> 5.72 | K21: EE Stacks | L21: 0 | S21: 20 | T21: =($D$8+(($O$3*(S21/100))*$N$7))*($F$8*-1)+($D$8+(($O$3*(S21/100))*$N$7)) -> 99.463896 | U21: =($N$7*(1+S21/100)*$N$6)*($F$8*-1)+($N$7*(1+S21/100)*$N$6) -> 99.463896 | V21: =$D$8*(($F$8-S21/100)*-1)+$D$8 -> 109.19978
B22: Active Damage | F22: spirit bonus | M22: Modified Spirit Multi 4 | O22: =(1-(J12-J13))*H15+J14 -> 0 | S22: 21 | T22: =($D$8+(($O$3*(S22/100))*$N$7))*($F$8*-1)+($D$8+(($O$3*(S22/100))*$N$7)) -> 100.29276 | U22: =($N$7*(1+S22/100)*$N$6)*($F$8*-1)+($N$7*(1+S22/100)*$N$6) -> 100.29276 | V22: =$D$8*(($F$8-S22/100)*-1)+$D$8 -> 110.51544
B23: Cold Front | C23: Phantom Strike | D23: Mystic Shot | E23: Arctic Blast | G23: all actives | M23: Modified Dmg+Spirit 4 | O23: =O22*H14 -> 0 | S23: 22 | T23: =($D$8+(($O$3*(S23/100))*$N$7))*($F$8*-1)+($D$8+(($O$3*(S23/100))*$N$7)) -> 101.12163 | U23: =($N$7*(1+S23/100)*$N$6)*($F$8*-1)+($N$7*(1+S23/100)*$N$6) -> 101.12163 | V23: =$D$8*(($F$8-S23/100)*-1)+$D$8 -> 111.8311
B24: =95+(B17*0.46) -> 123.52 | C24: =75+(B17*1) -> 137 | D24: 55 | E24: =175+(B17*0.7) -> 218.4 | G24: =B24+C24+D24+E24 -> 533.92 | M24: ABILITY DUMP | O24: FULL DUMP | S24: 23 | T24: =($D$8+(($O$3*(S24/100))*$N$7))*($F$8*-1)+($D$8+(($O$3*(S24/100))*$N$7)) -> 101.95049 | U24: =($N$7*(1+S24/100)*$N$6)*($F$8*-1)+($N$7*(1+S24/100)*$N$6) -> 101.95049 | V24: =$D$8*(($F$8-S24/100)*-1)+$D$8 -> 113.14676
A25: after res/shred | B25: =(B24*(1+J14)*(1-(J12-J13))) -> 104.992 | C25: =(C24*(1+J14)*(1-(J12-J13))) -> 116.45 | D25: =(D24*(1+J14)*(1-(J12-J13))) -> 46.75 | E25: =(E24*(1+J14)*(1-(J12-J13))) -> 185.64 | G25: =B25+C25+D25+E25 -> 453.832 | M25: =B21+D21+F21+H21 -> 419.39 | O25: =M25+G25 -> 873.222 | S25: 24 | T25: =($D$8+(($O$3*(S25/100))*$N$7))*($F$8*-1)+($D$8+(($O$3*(S25/100))*$N$7)) -> 102.77936 | U25: =($N$7*(1+S25/100)*$N$6)*($F$8*-1)+($N$7*(1+S25/100)*$N$6) -> 102.77936 | V25: =$D$8*(($F$8-S25/100)*-1)+$D$8 -> 114.46242
A26: DoT Calc | B26: uses ability 1 values | D26: increased duration | E26: 0.16 | S26: 25 | T26: =($D$8+(($O$3*(S26/100))*$N$7))*($F$8*-1)+($D$8+(($O$3*(S26/100))*$N$7)) -> 103.60823 | U26: =($N$7*(1+S26/100)*$N$6)*($F$8*-1)+($N$7*(1+S26/100)*$N$6) -> 103.60823 | V26: =$D$8*(($F$8-S26/100)*-1)+$D$8 -> 115.77808
A27: ability duration | B27: 3 | D27: added duration | E27: 0 | F27: total damage | G27: =B21*E28 -> 495.72 | H27: total more relevant for jg | S27: 26 | T27: =($D$8+(($O$3*(S27/100))*$N$7))*($F$8*-1)+($D$8+(($O$3*(S27/100))*$N$7)) -> 104.43709 | U27: =($N$7*(1+S27/100)*$N$6)*($F$8*-1)+($N$7*(1+S27/100)*$N$6) -> 104.43709 | V27: =$D$8*(($F$8-S27/100)*-1)+$D$8 -> 117.09374
A28: bonus duration | B28: 1 | D28: total duration | E28: =B27+E27+B28 -> 4 | F28: DPS | G28: =G27/E28 -> 123.93 | H28: dps more relevant for fighting | S28: 27 | T28: =($D$8+(($O$3*(S28/100))*$N$7))*($F$8*-1)+($D$8+(($O$3*(S28/100))*$N$7)) -> 105.26596 | U28: =($N$7*(1+S28/100)*$N$6)*($F$8*-1)+($N$7*(1+S28/100)*$N$6) -> 105.26596 | V28: =$D$8*(($F$8-S28/100)*-1)+$D$8 -> 118.4094
F29: dmg after resist | G29: =G27*(1-J12) -> 421.362 | S29: 28 | T29: =($D$8+(($O$3*(S29/100))*$N$7))*($F$8*-1)+($D$8+(($O$3*(S29/100))*$N$7)) -> 106.09482 | U29: =($N$7*(1+S29/100)*$N$6)*($F$8*-1)+($N$7*(1+S29/100)*$N$6) -> 106.09482 | V29: =$D$8*(($F$8-S29/100)*-1)+$D$8 -> 119.72506
S30: 29 | T30: =($D$8+(($O$3*(S30/100))*$N$7))*($F$8*-1)+($D$8+(($O$3*(S30/100))*$N$7)) -> 106.92369 | U30: =($N$7*(1+S30/100)*$N$6)*($F$8*-1)+($N$7*(1+S30/100)*$N$6) -> 106.92369 | V30: =$D$8*(($F$8-S30/100)*-1)+$D$8 -> 121.04072
A31: SPIRIT DMG | I31: Enemy Resist | J31: 0 | K31: Spirit Strike | L31: 0 | M31: Modified Spirit Multi 1 | O31: =(1-(J31-J32))*B34+J33 -> 0.3 | S31: 30 | T31: =($D$8+(($O$3*(S31/100))*$N$7))*($F$8*-1)+($D$8+(($O$3*(S31/100))*$N$7)) -> 107.75255 | U31: =($N$7*(1+S31/100)*$N$6)*($F$8*-1)+($N$7*(1+S31/100)*$N$6) -> 107.75255 | V31: =$D$8*(($F$8-S31/100)*-1)+$D$8 -> 122.35638
A32: Ability 1 | C32: Ability 2 | E32: Ability 3 | G32: Ultimate | I32: Resist Shred | J32: =1-(1-L31)*(1-L32)*(1-L33)*(1-L34) -> 0 | K32: Mystic Vuln | L32: 0 | M32: Modified Dmg+Spirit 1 | O32: =O31*B36 -> 8.1 | S32: 31 | T32: =($D$8+(($O$3*(S32/100))*$N$7))*($F$8*-1)+($D$8+(($O$3*(S32/100))*$N$7)) -> 108.58142 | U32: =($N$7*(1+S32/100)*$N$6)*($F$8*-1)+($N$7*(1+S32/100)*$N$6) -> 108.58142 | V32: =$D$8*(($F$8-S32/100)*-1)+$D$8 -> 123.67204
A33: Base Damage | B33: 50 | C33: Base Damage | D33: 40 | E33: Base Damage | F33: 15 | G33: Base Damage | H33: 0 | I33: Spirit Amp | J33: =L35+(L37*0.04) -> 0 | K33: EE | L33: 0 | S33: 32 | T33: =($D$8+(($O$3*(S33/100))*$N$7))*($F$8*-1)+($D$8+(($O$3*(S33/100))*$N$7)) -> 109.41029 | U33: =($N$7*(1+S33/100)*$N$6)*($F$8*-1)+($N$7*(1+S33/100)*$N$6) -> 109.41029 | V33: =$D$8*(($F$8-S33/100)*-1)+$D$8 -> 124.9877
A34: Spirit Multiplier | B34: 0.3 | C34: Spirit Multiplier | D34: 0.7 | E34: Spirit Multiplier | F34: 0.4 | G34: Spirit Multiplier | H34: 0 | K34: Crippling | L34: 0 | M34: Modified Spirit Multi 2 | O34: =(1-(J31-J32))*D34+J33 -> 0.7 | S34: 33 | T34: =($D$8+(($O$3*(S34/100))*$N$7))*($F$8*-1)+($D$8+(($O$3*(S34/100))*$N$7)) -> 110.23915 | U34: =($N$7*(1+S34/100)*$N$6)*($F$8*-1)+($N$7*(1+S34/100)*$N$6) -> 110.23915 | V34: =$D$8*(($F$8-S34/100)*-1)+$D$8 -> 126.30336
K35: Soulshredder | L35: 0 | M35: Modified Dmg+Spirit 2 | O35: =O34*D36 -> 18.9 | S35: 34 | T35: =($D$8+(($O$3*(S35/100))*$N$7))*($F$8*-1)+($D$8+(($O$3*(S35/100))*$N$7)) -> 111.06802 | U35: =($N$7*(1+S35/100)*$N$6)*($F$8*-1)+($N$7*(1+S35/100)*$N$6) -> 111.06802 | V35: =$D$8*(($F$8-S35/100)*-1)+$D$8 -> 127.61902
A36: Current Spirit | B36: 27 | C36: Current Spirit | D36: =B36 -> 27 | E36: Current Spirit | F36: =D36 -> 27 | G36: Current Spirit | H36: =F36 -> 27 | S36: 35 | T36: =($D$8+(($O$3*(S36/100))*$N$7))*($F$8*-1)+($D$8+(($O$3*(S36/100))*$N$7)) -> 111.89688 | U36: =($N$7*(1+S36/100)*$N$6)*($F$8*-1)+($N$7*(1+S36/100)*$N$6) -> 111.89688 | V36: =$D$8*(($F$8-S36/100)*-1)+$D$8 -> 128.93468
A37: Damage+Spirit | B37: =B34*B36 -> 8.1 | C37: Damage+Spirit | D37: =D34*D36 -> 18.9 | E37: Damage+Spirit | F37: =F34*F36 -> 10.8 | G37: Damage+Spirit | H37: =H34*H36 -> 0 | I37: Dmg Per Spirit | K37: EE Stacks | L37: 0 | M37: Modified Spirit Multi 3 | O37: =(1-(J31-J32))*F34+J33 -> 0.4 | S37: 36 | T37: =($D$8+(($O$3*(S37/100))*$N$7))*($F$8*-1)+($D$8+(($O$3*(S37/100))*$N$7)) -> 112.72575 | U37: =($N$7*(1+S37/100)*$N$6)*($F$8*-1)+($N$7*(1+S37/100)*$N$6) -> 112.72575 | V37: =$D$8*(($F$8-S37/100)*-1)+$D$8 -> 130.25034
A38: Raw Damage | B38: =B36*B34+B33 -> 58.1 | C38: Raw Damage | D38: =D36*D34+D33 -> 58.9 | E38: Raw Damage | F38: =F36*F34+F33 -> 25.8 | G38: Raw Damage | H38: =H36*H34+H33 -> 0 | I38: =O31+O34+O37+O41 -> 1.4 | M38: Modified Dmg+Spirit 3 | O38: =O37*F33 -> 6 | S38: 37 | T38: =($D$8+(($O$3*(S38/100))*$N$7))*($F$8*-1)+($D$8+(($O$3*(S38/100))*$N$7)) -> 113.55461 | U38: =($N$7*(1+S38/100)*$N$6)*($F$8*-1)+($N$7*(1+S38/100)*$N$6) -> 113.55461 | V38: =$D$8*(($F$8-S38/100)*-1)+$D$8 -> 131.566
A39: Modified Damage | C39: Modified Damage | E39: Modified Damage | G39: Modified Damage | I39: Dmg Per Spirit w/ Items | S39: 38 | T39: =($D$8+(($O$3*(S39/100))*$N$7))*($F$8*-1)+($D$8+(($O$3*(S39/100))*$N$7)) -> 114.38348 | U39: =($N$7*(1+S39/100)*$N$6)*($F$8*-1)+($N$7*(1+S39/100)*$N$6) -> 114.38348 | V39: =$D$8*(($F$8-S39/100)*-1)+$D$8 -> 132.88166
B40: =(B38*(1+J33)*(1-(J31-J32))) -> 58.1 | D40: =(D38*(1+J33)*(1-(J31-J32))) -> 58.9 | F40: =(F38*(1+J33)*(1-(J31-J32))) -> 25.8 | H40: =(H38*(1+J33)*(1-(J31+J32))) -> 0 | I40: =I38+1.5+1+0.5 -> 4.4 | S40: 39 | T40: =($D$8+(($O$3*(S40/100))*$N$7))*($F$8*-1)+($D$8+(($O$3*(S40/100))*$N$7)) -> 115.21235 | U40: =($N$7*(1+S40/100)*$N$6)*($F$8*-1)+($N$7*(1+S40/100)*$N$6) -> 115.21235 | V40: =$D$8*(($F$8-S40/100)*-1)+$D$8 -> 134.19732
...

Sheet Hero meta ranking
B1: ratings are out of 5 (minimum 1), all subject to personal opinion | ratings are based on a 'good' game on average, not a fantastic or shit one
A3: hero name | B3: Early | C3: Mid | D3: Late | E3: Nuke (spirit) | F3: Nuke (phys) | G3: Poke | H3: Crowd Control | I3: Engage | J3: Disengage | K3: Mobility | L3: Mid Contest | M3: Frontline | N3: Pick | O3: Support | P3: Wave Clear | Q3: Carry | R3: sustain dps (spirit) | S3: sustain dps (physical) | T3: average rank
A4: Viscous | B4: 4 | C4: 5 | D4: 4 | E4: 4 | F4: 4 | G4: 4 | H4: 4 | I4: 4 | J4: 5 | K4: 5 | L4: 5 | M4: 4 | N4: 1 | O4: 4 | P4: 4 | Q4: 5 | R4: 4 | S4: 3 | T4: =AVERAGE(J4:S4) -> 4
A5: Kelvin | B5: 5 | C5: 5 | D5: 4 | E5: 4 | F5: 1 | G5: 3 | H5: 4 | I5: 3 | J5: 3 | K5: 4 | L5: 5 | M5: 4 | N5: 4 | O5: 5 | P5: 4 | Q5: 3 | R5: 3 | S5: 3 | T5: =AVERAGE(J5:S5) -> 3.8
A6: Paradox | B6: 5 | C6: 5 | D6: 4 | E6: 4 | F6: 1 | G6: 5 | H6: 4 | I6: 5 | J6: 5 | K6: 4 | L6: 3 | M6: 2 | N6: 5 | O6: 3 | P6: 5 | Q6: 4 | R6: 3 | S6: 3 | T6: =AVERAGE(J6:S6) -> 3.7
A7: Billy | B7: 3 | C7: 5 | D7: 5 | E7: 1 | F7: 3 | G7: 1 | H7: 4 | I7: 5 | J7: 3 | K7: 3 | L7: 5 | M7: 5 | N7: 4 | O7: 1 | P7: 3 | Q7: 4 | R7: 1 | S7: 5 | T7: =AVERAGE(J7:S7) -> 3.4
A8: Holliday | B8: 4 | C8: 4 | D8: 5 | E8: 4 | F8: 4 | G8: 3 | H8: 5 | I8: 5 | J8: 5 | K8: 5 | L8: 3 | M8: 1 | N8: 5 | O8: 3 | P8: 4 | Q8: 4 | R8: 3 | S8: 4 | T8: =AVERAGE(J8:S8) -> 3.7
A9: Pocket | B9: 4 | C9: 5 | D9: 4 | E9: 5 | F9: 1 | G9: 2 | H9: 1 | I9: 5 | J9: 5 | K9: 5 | L9: 5 | M9: 1 | N9: 3 | O9: 1 | P9: 5 | Q9: 5 | R9: 5 | S9: 2 | T9: =AVERAGE(J9:S9) -> 3.7
A10: Seven | B10: 2 | C10: 3 | D10: 5 | E10: 5 | F10: 1 | G10: 1 | H10: 4 | I10: 2 | J10: 2 | K10: 4 | L10: 5 | M10: 1 | N10: 1 | O10: 1 | P10: 5 | Q10: 5 | R10: 5 | S10: 5 | T10: =AVERAGE(J10:S10) -> 3.4
A11: Ivy | B11: 3 | C11: 5 | D11: 4 | E11: 2 | F11: 1 | G11: 1 | H11: 2 | I11: 3 | J11: 4 | K11: 5 | L11: 4 | M11: 2 | N11: 1 | O11: 4 | P11: 5 | Q11: 4 | R11: 2 | S11: 3 | T11: =AVERAGE(J11:S11) -> 3.4
A12: Lash | B12: 1 | C12: 5 | D12: 4 | E12: 5 | F12: 1 | G12: 3 | H12: 4 | I12: 5 | J12: 5 | K12: 5 | L12: 4 | M12: 2 | N12: 4 | O12: 2 | P12: 4 | Q12: 3 | R12: 3 | S12: 2 | T12: =AVERAGE(J12:S12) -> 3.4
A13: McGinnis | B13: 4 | C13: 4 | D13: 4 | E13: 3 | F13: 1 | G13: 1 | H13: 3 | I13: 1 | J13: 2 | K13: 1 | L13: 4 | M13: 3 | N13: 1 | O13: 4 | P13: 3 | Q13: 5 | R13: 4 | S13: 5 | T13: =AVERAGE(J13:S13) -> 3.2
A14: Mina | B14: 5 | C14: 5 | D14: 4 | E14: 5 | F14: 1 | G14: 1 | H14: 2 | I14: 5 | J14: 5 | K14: 5 | L14: 3 | M14: 1 | N14: 3 | O14: 1 | P14: 4 | Q14: 4 | R14: 5 | S14: 1 | T14: =AVERAGE(J14:S14) -> 3.2
A15: Victor | B15: 5 | C15: 3 | D15: 5 | E15: 3 | F15: 1 | G15: 1 | H15: 2 | I15: 2 | J15: 2 | K15: 2 | L15: 4 | M15: 5 | N15: 1 | O15: 1 | P15: 2 | Q15: 5 | R15: 5 | S15: 5 | T15: =AVERAGE(J15:S15) -> 3.2
... A35: Paige | B35: 5 | C35: 3 | D35: 4 | E35: 3 | F35: 2 | G35: 3 | H35: 5 | I35: 1 | J35: 1 | K35: 1 | L35: 5 | M35: 1 | N35: 1 | O35: 5 | P35: 3 | Q35: 1 | R35: 2 | S35: 1 | T35: =AVERAGE(J35:S35) -> 2.1

Sheet boon item scaling
B1: item | G1: item | L1: item | Q1: item
B2: Veilwalker | G2: Headhunter | H2: (damage) | L2: Headhunter | M2: (heal) | Q2: test
A3: base effect | B3: 150 | C3: boon bonus | D3: 4 | F3: base effect | G3: 75 | H3: boon bonus | I3: 4 | K3: base effect | L3: 4 | M3: boon bonus | N3: 0.06 | P3: base effect | Q3: 85 | R3: boon bonus | S3: 6
A5: boon | B5: modified value | F5: boon | G5: modified value | K5: boon | L5: modified value | P5: boon | Q5: modified value
A6: 1 | B6: =$B$3+$D$3*A6 -> 154 | F6: 1 | G6: =$G$3+$I$3*F6 -> 79 | K6: 1 | L6: =$L$3+$N$3*K6 -> 4.06 | P6: 1 | Q6: =$Q$3+$S$3*P6 -> 91
A7: 2 | B7: =$B$3+$D$3*A7 -> 158 | F7: 2 | G7: =$G$3+$I$3*F7 -> 83 | K7: 2 | L7: =$L$3+$N$3*K7 -> 4.12 | P7: 2 | Q7: =$Q$3+$S$3*P7 -> 97
A8: 3 | B8: =$B$3+$D$3*A8 -> 162 | F8: 3 | G8: =$G$3+$I$3*F8 -> 87 | K8: 3 | L8: =$L$3+$N$3*K8 -> 4.18 | P8: 3 | Q8: =$Q$3+$S$3*P8 -> 103
A9: 4 | B9: =$B$3+$D$3*A9 -> 166 | F9: 4 | G9: =$G$3+$I$3*F9 -> 91 | K9: 4 | L9: =$L$3+$N$3*K9 -> 4.24 | P9: 4 | Q9: =$Q$3+$S$3*P9 -> 109
A10: 5 | B10: =$B$3+$D$3*A10 -> 170 | F10: 5 | G10: =$G$3+$I$3*F10 -> 95 | K10: 5 | L10: =$L$3+$N$3*K10 -> 4.3 | P10: 5 | Q10: =$Q$3+$S$3*P10 -> 115
A11: 6 | B11: =$B$3+$D$3*A11 -> 174 | F11: 6 | G11: =$G$3+$I$3*F11 -> 99 | K11: 6 | L11: =$L$3+$N$3*K11 -> 4.36 | P11: 6 | Q11: =$Q$3+$S$3*P11 -> 121
A12: 7 | B12: =$B$3+$D$3*A12 -> 178 | F12: 7 | G12: =$G$3+$I$3*F12 -> 103 | K12: 7 | L12: =$L$3+$N$3*K12 -> 4.42 | P12: 7 | Q12: =$Q$3+$S$3*P12 -> 127
A13: 8 | B13: =$B$3+$D$3*A13 -> 182 | F13: 8 | G13: =$G$3+$I$3*F13 -> 107 | K13: 8 | L13: =$L$3+$N$3*K13 -> 4.48 | P13: 8 | Q13: =$Q$3+$S$3*P13 -> 133
A14: 9 | B14: =$B$3+$D$3*A14 -> 186 | F14: 9 | G14: =$G$3+$I$3*F14 -> 111 | K14: 9 | L14: =$L$3+$N$3*K14 -> 4.54 | P14: 9 | Q14: =$Q$3+$S$3*P14 -> 139
A15: 10 | B15: =$B$3+$D$3*A15 -> 190 | F15: 10 | G15: =$G$3+$I$3*F15 -> 115 | K15: 10 | L15: =$L$3+$N$3*K15 -> 4.6 | P15: 10 | Q15: =$Q$3+$S$3*P15 -> 145
A16: 11 | B16: =$B$3+$D$3*A16 -> 194 | F16: 11 | G16: =$G$3+$I$3*F16 -> 119 | K16: 11 | L16: =$L$3+$N$3*K16 -> 4.66 | P16: 11 | Q16: =$Q$3+$S$3*P16 -> 151
A17: 12 | B17: =$B$3+$D$3*A17 -> 198 | F17: 12 | G17: =$G$3+$I$3*F17 -> 123 | K17: 12 | L17: =$L$3+$N$3*K17 -> 4.72 | P17: 12 | Q17: =$Q$3+$S$3*P17 -> 157
... A37: 32 | B37: =$B$3+$D$3*A37 -> 278 | F37: 32 | G37: =$G$3+$I$3*F37 -> 203 | K37: 32 | L37: =$L$3+$N$3*K37 -> 5.92 | P37: 32 | Q37: =$Q$3+$S$3*P37 -> 277

Sheet Damage Comparison
A1: BULLET DMG | J1: expressed as dps | L1: low comp | O1: expressed as dps | Q1: high comp | T1: expressed as dps | V1: user selected comparison | Y1: expressed as dps
A2: Hero | B2: Abrams | C2: Damage | D2: =VLOOKUP(B2, Heroes!$A$6:$H$53, 2, FALSE)*D5 -> 34.74 | G2: Boon Gain | H2: 1 | I2: =$D$3*H2+$D$2 -> 35.91 | J2: =I2*$D$4 -> 57.0969 | L2: Boon Gain | M2: 1 | N2: =$D$8*M2+$D$7 -> 7.59 | O2: =N2*$D$9 -> 30.1323 | Q2: Boon Gain | R2: 1 | S2: =$D$13*R2+$D$12 -> 6.92 | T2: =S2*$D$14 -> 82.348 | V2: Boon Gain | W2: 1 | X2: =$D$17*W2+$D$16 -> #N/A | Y2: =X2*$D$18 -> #N/A
A3: Boons | B3: 1 | C3: Damage Growth | D3: =VLOOKUP(B2, Heroes!$A$6:$S$53, 19, FALSE)*B3*D5 -> 1.17 | H3: 2 | I3: =$D$3*H3+$D$2 -> 37.08 | J3: =I3*$D$4 -> 58.9572 | M3: 2 | N3: =$D$8*M3+$D$7 -> 7.87 | O3: =N3*$D$9 -> 31.2439 | R3: 2 | S3: =$D$13*R3+$D$12 -> 7.12 | T3: =S3*$D$14 -> 84.728 | W3: 2 | X3: =$D$17*W3+$D$16 -> #N/A | Y3: =X3*$D$18 -> #N/A
C4: Fire Rate | D4: =VLOOKUP(B2, Heroes!$A$6:$H$53, 7, FALSE) -> 1.59 | H4: 3 | I4: =$D$3*H4+$D$2 -> 38.25 | J4: =I4*$D$4 -> 60.8175 | M4: 3 | N4: =$D$8*M4+$D$7 -> 8.15 | O4: =N4*$D$9 -> 32.3555 | R4: 3 | S4: =$D$13*R4+$D$12 -> 7.32 | T4: =S4*$D$14 -> 87.108 | W4: 3 | X4: =$D$17*W4+$D$16 -> #N/A | Y4: =X4*$D$18 -> #N/A
C5: Pellets | D5: =VLOOKUP(B2, Heroes!$A$6:$H$53, 3, FALSE) -> 9 | H5: 4 | I5: =$D$3*H5+$D$2 -> 39.42 | J5: =I5*$D$4 -> 62.6778 | M5: 4 | N5: =$D$8*M5+$D$7 -> 8.43 | O5: =N5*$D$9 -> 33.4671 | R5: 4 | S5: =$D$13*R5+$D$12 -> 7.52 | T5: =S5*$D$14 -> 89.488 | W5: 4 | X5: =$D$17*W5+$D$16 -> #N/A | Y5: =X5*$D$18 -> #N/A
A6: BULLET DMG | B6: comparable low | H6: 5 | I6: =$D$3*H6+$D$2 -> 40.59 | J6: =I6*$D$4 -> 64.5381 | M6: 5 | N6: =$D$8*M6+$D$7 -> 8.71 | O6: =N6*$D$9 -> 34.5787 | R6: 5 | S6: =$D$13*R6+$D$12 -> 7.72 | T6: =S6*$D$14 -> 91.868 | W6: 5 | X6: =$D$17*W6+$D$16 -> #N/A | Y6: =X6*$D$18 -> #N/A
A7: Hero | B7: Mina | C7: Damage | D7: =VLOOKUP(B7, Heroes!$A$6:$H$53, 2, FALSE) -> 7.31 | H7: 6 | I7: =$D$3*H7+$D$2 -> 41.76 | J7: =I7*$D$4 -> 66.3984 | M7: 6 | N7: =$D$8*M7+$D$7 -> 8.99 | O7: =N7*$D$9 -> 35.6903 | R7: 6 | S7: =$D$13*R7+$D$12 -> 7.92 | T7: =S7*$D$14 -> 94.248 | W7: 6 | X7: =$D$17*W7+$D$16 -> #N/A | Y7: =X7*$D$18 -> #N/A
A8: Boons | B8: 1 | C8: Damage Growth | D8: =VLOOKUP(B7, Heroes!$A$6:$S$53, 19, FALSE)*B8*D10 -> 0.28 | H8: 7 | I8: =$D$3*H8+$D$2 -> 42.93 | J8: =I8*$D$4 -> 68.2587 | M8: 7 | N8: =$D$8*M8+$D$7 -> 9.27 | O8: =N8*$D$9 -> 36.8019 | R8: 7 | S8: =$D$13*R8+$D$12 -> 8.12 | T8: =S8*$D$14 -> 96.628 | W8: 7 | X8: =$D$17*W8+$D$16 -> #N/A | Y8: =X8*$D$18 -> #N/A
C9: Fire Rate | D9: =VLOOKUP(B7, Heroes!$A$6:$H$53, 7, FALSE) -> 3.97 | H9: 8 | I9: =$D$3*H9+$D$2 -> 44.1 | J9: =I9*$D$4 -> 70.119 | M9: 8 | N9: =$D$8*M9+$D$7 -> 9.55 | O9: =N9*$D$9 -> 37.9135 | R9: 8 | S9: =$D$13*R9+$D$12 -> 8.32 | T9: =S9*$D$14 -> 99.008 | W9: 8 | X9: =$D$17*W9+$D$16 -> #N/A | Y9: =X9*$D$18 -> #N/A
C10: Pellets | D10: =VLOOKUP(B7, Heroes!$A$6:$H$53, 3, FALSE) -> 1 | H10: 9 | I10: =$D$3*H10+$D$2 -> 45.27 | J10: =I10*$D$4 -> 71.9793 | M10: 9 | N10: =$D$8*M10+$D$7 -> 9.83 | O10: =N10*$D$9 -> 39.0251 | R10: 9 | S10: =$D$13*R10+$D$12 -> 8.52 | T10: =S10*$D$14 -> 101.388 | W10: 9 | X10: =$D$17*W10+$D$16 -> #N/A | Y10: =X10*$D$18 -> #N/A
A11: BULLET DMG | B11: comparable high | H11: 10 | I11: =$D$3*H11+$D$2 -> 46.44 | J11: =I11*$D$4 -> 73.8396 | M11: 10 | N11: =$D$8*M11+$D$7 -> 10.11 | O11: =N11*$D$9 -> 40.1367 | R11: 10 | S11: =$D$13*R11+$D$12 -> 8.72 | T11: =S11*$D$14 -> 103.768 | W11: 10 | X11: =$D$17*W11+$D$16 -> #N/A | Y11: =X11*$D$18 -> #N/A
A12: Hero | B12: McGinnis | C12: Damage | D12: =VLOOKUP(B12, Heroes!$A$6:$H$53, 2, FALSE) -> 6.72 | H12: 11 | I12: =$D$3*H12+$D$2 -> 47.61 | J12: =I12*$D$4 -> 75.6999 | M12: 11 | N12: =$D$8*M12+$D$7 -> 10.39 | O12: =N12*$D$9 -> 41.2483 | R12: 11 | S12: =$D$13*R12+$D$12 -> 8.92 | T12: =S12*$D$14 -> 106.148 | W12: 11 | X12: =$D$17*W12+$D$16 -> #N/A | Y12: =X12*$D$18 -> #N/A
A13: Boons | B13: 1 | C13: Damage Growth | D13: =VLOOKUP(B12, Heroes!$A$6:$S$53, 19, FALSE)*B13*B14 -> 0.2 | H13: 12 | I13: =$D$3*H13+$D$2 -> 48.78 | J13: =I13*$D$4 -> 77.5602 | M13: 12 | N13: =$D$8*M13+$D$7 -> 10.67 | O13: =N13*$D$9 -> 42.3599 | R13: 12 | S13: =$D$13*R13+$D$12 -> 9.12 | T13: =S13*$D$14 -> 108.528 | W13: 12 | X13: =$D$17*W13+$D$16 -> #N/A | Y13: =X13*$D$18 -> #N/A
A14: Pellets | B14: =VLOOKUP(B12, Heroes!$A$6:$H$53, 3, FALSE) -> 1 | C14: Fire Rate | D14: =VLOOKUP(B12, Heroes!$A$6:$H$53, 7, FALSE) -> 11.9 | H14: 13 | I14: =$D$3*H14+$D$2 -> 49.95 | J14: =I14*$D$4 -> 79.4205 | M14: 13 | N14: =$D$8*M14+$D$7 -> 10.95 | O14: =N14*$D$9 -> 43.4715 | R14: 13 | S14: =$D$13*R14+$D$12 -> 9.32 | T14: =S14*$D$14 -> 110.908 | W14: 13 | X14: =$D$17*W14+$D$16 -> #N/A | Y14: =X14*$D$18 -> #N/A
A15: BULLET DMG | B15: specific comparator | H15: 14 | I15: =$D$3*H15+$D$2 -> 51.12 | J15: =I15*$D$4 -> 81.2808 | M15: 14 | N15: =$D$8*M15+$D$7 -> 11.23 | O15: =N15*$D$9 -> 44.5831 | R15: 14 | S15: =$D$13*R15+$D$12 -> 9.52 | T15: =S15*$D$14 -> 113.288 | W15: 14 | X15: =$D$17*W15+$D$16 -> #N/A | Y15: =X15*$D$18 -> #N/A
A16: Hero | B16: Warden | C16: Damage | D16: =VLOOKUP(B16, Heroes!$A$6:$H$53, 2, FALSE)*B18 -> #N/A | H16: 15 | I16: =$D$3*H16+$D$2 -> 52.29 | J16: =I16*$D$4 -> 83.1411 | M16: 15 | N16: =$D$8*M16+$D$7 -> 11.51 | O16: =N16*$D$9 -> 45.6947 | R16: 15 | S16: =$D$13*R16+$D$12 -> 9.72 | T16: =S16*$D$14 -> 115.668 | W16: 15 | X16: =$D$17*W16+$D$16 -> #N/A | Y16: =X16*$D$18 -> #N/A
A17: Boons | B17: 1 | C17: Damage Growth | D17: =(VLOOKUP(B16, Heroes!$A$6:$S$53, 19, FALSE)*B17)*B18 -> #N/A | H17: 16 | I17: =$D$3*H17+$D$2 -> 53.46 | J17: =I17*$D$4 -> 85.0014 | M17: 16 | N17: =$D$8*M17+$D$7 -> 11.79 | O17: =N17*$D$9 -> 46.8063 | R17: 16 | S17: =$D$13*R17+$D$12 -> 9.92 | T17: =S17*$D$14 -> 118.048 | W17: 16 | X17: =$D$17*W17+$D$16 -> #N/A | Y17: =X17*$D$18 -> #N/A
A18: Pellets | B18: =VLOOKUP(B16, Heroes!$A$6:$H$36, 3, FALSE) -> #N/A | C18: Fire Rate | D18: =VLOOKUP(B16, Heroes!$A$6:$H$53, 7, FALSE) -> 4.19 | H18: 17 | I18: =$D$3*H18+$D$2 -> 54.63 | J18: =I18*$D$4 -> 86.8617 | M18: 17 | N18: =$D$8*M18+$D$7 -> 12.07 | O18: =N18*$D$9 -> 47.9179 | R18: 17 | S18: =$D$13*R18+$D$12 -> 10.12 | T18: =S18*$D$14 -> 120.428 | W18: 17 | X18: =$D$17*W18+$D$16 -> #N/A | Y18: =X18*$D$18 -> #N/A
H19: 18 | I19: =$D$3*H19+$D$2 -> 55.8 | J19: =I19*$D$4 -> 88.722 | M19: 18 | N19: =$D$8*M19+$D$7 -> 12.35 | O19: =N19*$D$9 -> 49.0295 | R19: 18 | S19: =$D$13*R19+$D$12 -> 10.32 | T19: =S19*$D$14 -> 122.808 | W19: 18 | X19: =$D$17*W19+$D$16 -> #N/A | Y19: =X19*$D$18 -> #N/A
H20: 19 | I20: =$D$3*H20+$D$2 -> 56.97 | J20: =I20*$D$4 -> 90.5823 | M20: 19 | N20: =$D$8*M20+$D$7 -> 12.63 | O20: =N20*$D$9 -> 50.1411 | R20: 19 | S20: =$D$13*R20+$D$12 -> 10.52 | T20: =S20*$D$14 -> 125.188 | W20: 19 | X20: =$D$17*W20+$D$16 -> #N/A | Y20: =X20*$D$18 -> #N/A
H21: 20 | I21: =$D$3*H21+$D$2 -> 58.14 | J21: =I21*$D$4 -> 92.4426 | M21: 20 | N21: =$D$8*M21+$D$7 -> 12.91 | O21: =N21*$D$9 -> 51.2527 | R21: 20 | S21: =$D$13*R21+$D$12 -> 10.72 | T21: =S21*$D$14 -> 127.568 | W21: 20 | X21: =$D$17*W21+$D$16 -> #N/A | Y21: =X21*$D$18 -> #N/A
H22: 21 | I22: =$D$3*H22+$D$2 -> 59.31 | J22: =I22*$D$4 -> 94.3029 | M22: 21 | N22: =$D$8*M22+$D$7 -> 13.19 | O22: =N22*$D$9 -> 52.3643 | R22: 21 | S22: =$D$13*R22+$D$12 -> 10.92 | T22: =S22*$D$14 -> 129.948 | W22: 21 | X22: =$D$17*W22+$D$16 -> #N/A | Y22: =X22*$D$18 -> #N/A
H23: 22 | I23: =$D$3*H23+$D$2 -> 60.48 | J23: =I23*$D$4 -> 96.1632 | M23: 22 | N23: =$D$8*M23+$D$7 -> 13.47 | O23: =N23*$D$9 -> 53.4759 | R23: 22 | S23: =$D$13*R23+$D$12 -> 11.12 | T23: =S23*$D$14 -> 132.328 | W23: 22 | X23: =$D$17*W23+$D$16 -> #N/A | Y23: =X23*$D$18 -> #N/A
H24: 23 | I24: =$D$3*H24+$D$2 -> 61.65 | J24: =I24*$D$4 -> 98.0235 | M24: 23 | N24: =$D$8*M24+$D$7 -> 13.75 | O24: =N24*$D$9 -> 54.5875 | R24: 23 | S24: =$D$13*R24+$D$12 -> 11.32 | T24: =S24*$D$14 -> 134.708 | W24: 23 | X24: =$D$17*W24+$D$16 -> #N/A | Y24: =X24*$D$18 -> #N/A
H25: 24 | I25: =$D$3*H25+$D$2 -> 62.82 | J25: =I25*$D$4 -> 99.8838 | M25: 24 | N25: =$D$8*M25+$D$7 -> 14.03 | O25: =N25*$D$9 -> 55.6991 | R25: 24 | S25: =$D$13*R25+$D$12 -> 11.52 | T25: =S25*$D$14 -> 137.088 | W25: 24 | X25: =$D$17*W25+$D$16 -> #N/A | Y25: =X25*$D$18 -> #N/A
H26: 25 | I26: =$D$3*H26+$D$2 -> 63.99 | J26: =I26*$D$4 -> 101.7441 | M26: 25 | N26: =$D$8*M26+$D$7 -> 14.31 | O26: =N26*$D$9 -> 56.8107 | R26: 25 | S26: =$D$13*R26+$D$12 -> 11.72 | T26: =S26*$D$14 -> 139.468 | W26: 25 | X26: =$D$17*W26+$D$16 -> #N/A | Y26: =X26*$D$18 -> #N/A
H27: 26 | I27: =$D$3*H27+$D$2 -> 65.16 | J27: =I27*$D$4 -> 103.6044 | M27: 26 | N27: =$D$8*M27+$D$7 -> 14.59 | O27: =N27*$D$9 -> 57.9223 | R27: 26 | S27: =$D$13*R27+$D$12 -> 11.92 | T27: =S27*$D$14 -> 141.848 | W27: 26 | X27: =$D$17*W27+$D$16 -> #N/A | Y27: =X27*$D$18 -> #N/A
H28: 27 | I28: =$D$3*H28+$D$2 -> 66.33 | J28: =I28*$D$4 -> 105.4647 | M28: 27 | N28: =$D$8*M28+$D$7 -> 14.87 | O28: =N28*$D$9 -> 59.0339 | R28: 27 | S28: =$D$13*R28+$D$12 -> 12.12 | T28: =S28*$D$14 -> 144.228 | W28: 27 | X28: =$D$17*W28+$D$16 -> #N/A | Y28: =X28*$D$18 -> #N/A
H29: 28 | I29: =$D$3*H29+$D$2 -> 67.5 | J29: =I29*$D$4 -> 107.325 | M29: 28 | N29: =$D$8*M29+$D$7 -> 15.15 | O29: =N29*$D$9 -> 60.1455 | R29: 28 | S29: =$D$13*R29+$D$12 -> 12.32 | T29: =S29*$D$14 -> 146.608 | W29: 28 | X29: =$D$17*W29+$D$16 -> #N/A | Y29: =X29*$D$18 -> #N/A
H30: 29 | I30: =$D$3*H30+$D$2 -> 68.67 | J30: =I30*$D$4 -> 109.1853 | M30: 29 | N30: =$D$8*M30+$D$7 -> 15.43 | O30: =N30*$D$9 -> 61.2571 | R30: 29 | S30: =$D$13*R30+$D$12 -> 12.52 | T30: =S30*$D$14 -> 148.988 | W30: 29 | X30: =$D$17*W30+$D$16 -> #N/A | Y30: =X30*$D$18 -> #N/A
... H33: 32 | I33: =$D$3*H33+$D$2 -> 72.18 | J33: =I33*$D$4 -> 114.7662 | M33: 32 | N33: =$D$8*M33+$D$7 -> 16.27 | O33: =N33*$D$9 -> 64.5919 | R33: 32 | S33: =$D$13*R33+$D$12 -> 13.12 | T33: =S33*$D$14 -> 156.128 | W33: 32 | X33: =$D$17*W33+$D$16 -> #N/A | Y33: =X33*$D$18 -> #N/A

Sheet Hidden Mechanics
A2: Shiv Rage | D2: Lycan Transform
A3: Drain Rate | B3: 0.35/s | D3: Rage Per Dmg | E3: 0.255
A4: Bullet Dmg Gain | B4: 0.017 | D4: Max Rage | E4: 100
A5: Spirit Dmg Gain | B5: 0.014 | D5: Rage Per Boon | E5: 11
A6: Light Melee Rage | B6: 1.5 | D6: Crit Reduction | E6: 0.2
A7: Heavy Melee | B7: 3.5 | D7: Rage Decay | E7: 0.03 | F7: out of combat triggers decay
A8: Max Rage | B8: 10 | D8: Low HP Value | E8: 30 | F8: decay does not count as in combat, so your rage will decay while it's active
A9: NPC Scaling | B9: 0.2 | D9: Low HP Bonus | E9: 40
A10: Rage Decay Delay | B10: 7 | D10: Low HP Scaling | E10: 1.8
A11: Execute HP Buffer | B11: 0.03 | D11: Stack Duration | E11: 5
A12: Execute Movespeed | B12: 25m/s | D12: Combat Rage | E12: 0.01 | F12: in combat builds at this rate
A14: Wraith Card | D14: boon | E14: dmg required | F14: previous
A15: Resource Per Card | B15: 100 | D15: 1 | E15: =($E$5*D15+$E$4)/$E$3 -> 435.29412 | F15: 435
A16: NPC Scaling | B16: 0.35 | D16: 17 | E16: =($E$5*D16+$E$4)/$E$3 -> 1125.4902 | F16: 800
A17: Resource Per Bullet | B17: 4 | D17: 35 | E17: =($E$5*D17+$E$4)/$E$3 -> 1901.9608 | F17: 1400
A18: Resource Per Crit | B18: 6
A19: Resource Per Light Melee | B19: 20
A20: Resource Per Heavy Melee | B20: 50
A21: Light Melee (npc) | B21: =B19*B16 -> 7
A22: Heavy Melee (npc) | B22: =B20*B16 -> 17.5 | L22: tesla | M22: chance | N22: icd | O22: primary dmg | P22: cdr | Q22: modified icd | S22: fire rate | T22: inc fire rate | U22: modified fire rate
A23: Cooldown Reduction Scale | B23: 0.06 | M23: 0.15 | N23: 0.25 | O23: 40 | P23: 0 | Q23: =N23*(1-P23) -> 0.25 | S23: 10.6 | T23: 1.46 | U23: =S23*(1+T23) -> 26.076
A25: Diminishing Return | M25: bps required to proc on cd on average
A26: Chance | M26: =(1/Q23)/M23 -> 26.666667
A27: 0.4 | B27: 0.35 | C27: 0.3 | D27: 0.4 | E27: 0.45 | F27: 0.7
A28: Real | B28: Expected | L28: capacitor | M28: chance | N28: icd | O28: primary dmg | P28: cdr | Q28: modified icd | S28: fire rate | T28: inc fire rate | U28: modified fire rate
A29: =1-(1-A27)*(1-B27)*(1-C27)*(1-D27)*(1-E27)*(1-F27) -> 0.972973 | B29: =sum(A27:F27) -> 2.6 | M29: 0.2 | N29: 0.25 | O29: 50 | P29: 0 | Q29: =N29*(1-P29) -> 0.25 | S29: 10.6 | T29: 1.46 | U29: =S29*(1+T29) -> 26.076
M31: bps required to proc on cd on average
M32: =(1/Q29)/M29 -> 20
G37: haze dmg chart w/ weapon dmg
A38: fixation damage | B38: haze dmg | C38: weapon dmg | D38: shred | E38: fixation stacks | F38: fixation | G38: haze dmg | H38: weapon dmg | I38: dmg per shot | J38: dps | K38: shred
A39: 0.2 | B39: 7.77 | C39: 0 | D39: 0 | E39: 1 | F39: =E39*$A$39 -> 0.2 | G39: =$B$39 -> 7.77 | H39: =G39+G39*$C$39 -> 7.77 | I39: =H39+F39 -> 7.97 | J39: =$C$42*I39 -> 87.67 | K39: =J39*(1+$D$39) -> 87.67
E40: 2 | F40: =E40*$A$39 -> 0.4 | G40: =$B$39 -> 7.77 | H40: =G40+G40*$C$39 -> 7.77 | I40: =H40+F40 -> 8.17 | J40: =$C$42*I40 -> 89.87 | K40: =J40*(1+$D$39) -> 89.87
A41: fire rate | B41: fire rate % | C41: shots per sec | D41: max stack time | E41: 3 | F41: =E41*$A$39 -> 0.6 | G41: =$B$39 -> 7.77 | H41: =G41+G41*$C$39 -> 7.77 | I41: =H41+F41 -> 8.37 | J41: =$C$42*I41 -> 92.07 | K41: =J41*(1+$D$39) -> 92.07
A42: 10 | B42: 0.1 | C42: =A42+A42*B42 -> 11 | D42: =80/C42 -> 7.2727273 | E42: 4 | F42: =E42*$A$39 -> 0.8 | G42: =$B$39 -> 7.77 | H42: =G42+G42*$C$39 -> 7.77 | I42: =H42+F42 -> 8.57 | J42: =$C$42*I42 -> 94.27 | K42: =J42*(1+$D$39) -> 94.27
E43: 5 | F43: =E43*$A$39 -> 1 | G43: =$B$39 -> 7.77 | H43: =G43+G43*$C$39 -> 7.77 | I43: =H43+F43 -> 8.77 | J43: =$C$42*I43 -> 96.47 | K43: =J43*(1+$D$39) -> 96.47
A44: trooper group soul value | B44: %split | C44: souls per player | D44: total souls | E44: 6 | F44: =E44*$A$39 -> 1.2 | G44: =$B$39 -> 7.77 | H44: =G44+G44*$C$39 -> 7.77 | I44: =H44+F44 -> 8.97 | J44: =$C$42*I44 -> 98.67 | K44: =J44*(1+$D$39) -> 98.67
A45: 1 | B45: 1 | C45: =$B$53*B45/A45 -> 480 | D45: =C45*A45 -> 480 | E45: 7 | F45: =E45*$A$39 -> 1.4 | G45: =$B$39 -> 7.77 | H45: =G45+G45*$C$39 -> 7.77 | I45: =H45+F45 -> 9.17 | J45: =$C$42*I45 -> 100.87 | K45: =J45*(1+$D$39) -> 100.87
A46: 2 | B46: 1.3 | C46: =$B$53*B46/A46 -> 312 | D46: =C46*A46 -> 624 | E46: 8 | F46: =E46*$A$39 -> 1.6 | G46: =$B$39 -> 7.77 | H46: =G46+G46*$C$39 -> 7.77 | I46: =H46+F46 -> 9.37 | J46: =$C$42*I46 -> 103.07 | K46: =J46*(1+$D$39) -> 103.07
A47: 3 | B47: 0.9 | C47: =$B$53*B47/A47 -> 144 | D47: =C47*A47 -> 432 | E47: 9 | F47: =E47*$A$39 -> 1.8 | G47: =$B$39 -> 7.77 | H47: =G47+G47*$C$39 -> 7.77 | I47: =H47+F47 -> 9.57 | J47: =$C$42*I47 -> 105.27 | K47: =J47*(1+$D$39) -> 105.27
A48: 4 | B48: 0.8 | C48: =$B$53*B48/A48 -> 96 | D48: =C48*A48 -> 384 | E48: 10 | F48: =E48*$A$39 -> 2 | G48: =$B$39 -> 7.77 | H48: =G48+G48*$C$39 -> 7.77 | I48: =H48+F48 -> 9.77 | J48: =$C$42*I48 -> 107.47 | K48: =J48*(1+$D$39) -> 107.47
...

Sheet shopBonuses
B2: Weapon | C2: inc from previous | E2: Vitality | H2: Spirit | K2: random quick notes
A3: 800 | B3: 7 | C3: - | D3: 800 | E3: 8 | F3: - | G3: 800 | H3: 7 | I3: - | K3: weapon 3.2 and 9.6 big increases
A4: 1600 | B4: 9 | C4: =B4/B3-1 -> 0.28571429 | D4: 1600 | E4: 10 | F4: =E4/E3-1 -> 0.25 | G4: 1600 | H4: 11 | I4: =H4/H3-1 -> 0.57142857 | K4: vit ~4.8 probably enough
A5: 2400 | B5: 13 | C5: =B5/B4-1 -> 0.44444444 | D5: 2400 | E5: 13 | F5: =E5/E4-1 -> 0.3 | G5: 2400 | H5: 15 | I5: =H5/H4-1 -> 0.36363636 | K5: spirit benefit and priority depends greatly on your hero and ratios, additionally how many damaging items you buy // at least recommend getting a single 1600 item if you are not intending to go spirit
A6: 3200 | B6: 20 | C6: =B6/B5-1 -> 0.53846154 | D6: 3200 | E6: 17 | F6: =E6/E5-1 -> 0.30769231 | G6: 3200 | H6: 19 | I6: =H6/H5-1 -> 0.26666667
A7: 4800 | B7: 29 | C7: =B7/B6-1 -> 0.45 | D7: 4800 | E7: 22 | F7: =E7/E6-1 -> 0.29411765 | G7: 4800 | H7: 25 | I7: =H7/H6-1 -> 0.31578947
A8: 7200 | B8: 40 | C8: =B8/B7-1 -> 0.37931034 | D8: 7200 | E8: 27 | F8: =E8/E7-1 -> 0.22727273 | G8: 7200 | H8: 32 | I8: =H8/H7-1 -> 0.28
A9: 9600 | B9: 60 | C9: =B9/B8-1 -> 0.5 | D9: 9600 | E9: 32 | F9: =E9/E8-1 -> 0.18518519 | G9: 9600 | H9: 44 | I9: =H9/H8-1 -> 0.375
A10: 16000 | B10: 75 | C10: =B10/B9-1 -> 0.25 | D10: 16000 | E10: 36 | F10: =E10/E9-1 -> 0.125 | G10: 16000 | H10: 56 | I10: =H10/H9-1 -> 0.27272727
A11: 22400 | B11: 95 | C11: =B11/B10-1 -> 0.26666667 | D11: 22400 | E11: 40 | F11: =E11/E10-1 -> 0.11111111 | G11: 22400 | H11: 69 | I11: =H11/H10-1 -> 0.23214286
A12: 28800 | B12: 115 | C12: =B12/B11-1 -> 0.21052632 | D12: 28800 | E12: 44 | F12: =E12/E11-1 -> 0.1 | G12: 28800 | H12: 81 | I12: =H12/H11-1 -> 0.17391304
B13: 0 | E13: 0 | H13: 0

Sheet Neutral
A2: Midboss | B2: HP | F2: Denizens | G2: Small | H2: Medium | I2: Ancient | J2: Vault | M2: cultist | N2: Small | O2: Medium | P2: Ancient
B3: 13000 | F3: base souls | G3: 51 | H3: 84 | I3: 225 | J3: 327 | K3: <-- from minute 0 | M3: base souls | N3: 51 | O3: 84 | P3: 225
C4: minute | D4: dmg shield | F4: spm | G4: 0.55 | H4: 0.91 | I4: 2.43 | J4: 3.53 | M4: spm | N4: 0.55 | O4: 0.91 | P4: 2.43
C5: 0 | D5: 35 | F5: 0 | G5: 51 | H5: 84 | I5: 225 | J5: 327 | N5: =G5+G5+(G5*0.5) -> 127.5 | O5: =H5+H5+(H5*0.5) -> 210 | P5: =I5+I5+(I5*0.5) -> 562.5
C6: 1 | D6: 40 | F6: 1 | G6: =G5+0.55 -> 51.55 | H6: =H5+0.91 -> 84.91 | I6: =I5+2.43 -> 227.43 | J6: =J5+3.53 -> 330.53 | N6: =G6+G6+(G6*0.5) -> 128.875 | O6: =H6+H6+(H6*0.5) -> 212.275 | P6: =I6+I6+(I6*0.5) -> 568.575
C7: 2 | D7: 45 | F7: 2 | G7: =G6+0.55 -> 52.1 | H7: =H6+0.91 -> 85.82 | I7: =I6+2.43 -> 229.86 | J7: =J6+3.53 -> 334.06 | N7: =G7+G7+(G7*0.5) -> 130.25 | O7: =H7+H7+(H7*0.5) -> 214.55 | P7: =I7+I7+(I7*0.5) -> 574.65
C8: 3 | D8: 50 | F8: 3 | G8: =G7+0.55 -> 52.65 | H8: =H7+0.91 -> 86.73 | I8: =I7+2.43 -> 232.29 | J8: =J7+3.53 -> 337.59 | N8: =G8+G8+(G8*0.5) -> 131.625 | O8: =H8+H8+(H8*0.5) -> 216.825 | P8: =I8+I8+(I8*0.5) -> 580.725
C9: 4 | D9: 55 | F9: 4 | G9: =G8+0.55 -> 53.2 | H9: =H8+0.91 -> 87.64 | I9: =I8+2.43 -> 234.72 | J9: =J8+3.53 -> 341.12 | N9: =G9+G9+(G9*0.5) -> 133 | O9: =H9+H9+(H9*0.5) -> 219.1 | P9: =I9+I9+(I9*0.5) -> 586.8
C10: 5 | D10: 60 | F10: 5 | G10: =G9+0.55 -> 53.75 | H10: =H9+0.91 -> 88.55 | I10: =I9+2.43 -> 237.15 | J10: =J9+3.53 -> 344.65 | N10: =G10+G10+(G10*0.5) -> 134.375 | O10: =H10+H10+(H10*0.5) -> 221.375 | P10: =I10+I10+(I10*0.5) -> 592.875
C11: 6 | D11: 65 | F11: 6 | G11: =G10+0.55 -> 54.3 | H11: =H10+0.91 -> 89.46 | I11: =I10+2.43 -> 239.58 | J11: =J10+3.53 -> 348.18 | N11: =G11+G11+(G11*0.5) -> 135.75 | O11: =H11+H11+(H11*0.5) -> 223.65 | P11: =I11+I11+(I11*0.5) -> 598.95
C12: 7 | D12: 70 | F12: 7 | G12: =G11+0.55 -> 54.85 | H12: =H11+0.91 -> 90.37 | I12: =I11+2.43 -> 242.01 | J12: =J11+3.53 -> 351.71 | N12: =G12+G12+(G12*0.5) -> 137.125 | O12: =H12+H12+(H12*0.5) -> 225.925 | P12: =I12+I12+(I12*0.5) -> 605.025
C13: 8 | D13: 75 | F13: 8 | G13: =G12+0.55 -> 55.4 | H13: =H12+0.91 -> 91.28 | I13: =I12+2.43 -> 244.44 | J13: =J12+3.53 -> 355.24 | K13: <-- vaults/ancients | N13: =G13+G13+(G13*0.5) -> 138.5 | O13: =H13+H13+(H13*0.5) -> 228.2 | P13: =I13+I13+(I13*0.5) -> 611.1 | Q13: <-- vaults/ancients
C14: 9 | D14: 80 | F14: 9 | G14: =G13+0.55 -> 55.95 | H14: =H13+0.91 -> 92.19 | I14: =I13+2.43 -> 246.87 | J14: =J13+3.53 -> 358.77 | N14: =G14+G14+(G14*0.5) -> 139.875 | O14: =H14+H14+(H14*0.5) -> 230.475 | P14: =I14+I14+(I14*0.5) -> 617.175
A15: when he can spawn | B15: --> | C15: 10 | D15: 85 | F15: 10 | G15: =G14+0.55 -> 56.5 | H15: =H14+0.91 -> 93.1 | I15: =I14+2.43 -> 249.3 | J15: =J14+3.53 -> 362.3 | N15: =G15+G15+(G15*0.5) -> 141.25 | O15: =H15+H15+(H15*0.5) -> 232.75 | P15: =I15+I15+(I15*0.5) -> 623.25
C16: 11 | D16: 90 | F16: 11 | G16: =G15+0.55 -> 57.05 | H16: =H15+0.91 -> 94.01 | I16: =I15+2.43 -> 251.73 | J16: =J15+3.53 -> 365.83 | N16: =G16+G16+(G16*0.5) -> 142.625 | O16: =H16+H16+(H16*0.5) -> 235.025 | P16: =I16+I16+(I16*0.5) -> 629.325
C17: 12 | D17: 95 | F17: 12 | G17: =G16+0.55 -> 57.6 | H17: =H16+0.91 -> 94.92 | I17: =I16+2.43 -> 254.16 | J17: =J16+3.53 -> 369.36 | N17: =G17+G17+(G17*0.5) -> 144 | O17: =H17+H17+(H17*0.5) -> 237.3 | P17: =I17+I17+(I17*0.5) -> 635.4
C18: 13 | D18: 100 | F18: 13 | G18: =G17+0.55 -> 58.15 | H18: =H17+0.91 -> 95.83 | I18: =I17+2.43 -> 256.59 | J18: =J17+3.53 -> 372.89 | N18: =G18+G18+(G18*0.5) -> 145.375 | O18: =H18+H18+(H18*0.5) -> 239.575 | P18: =I18+I18+(I18*0.5) -> 641.475
C19: 14 | D19: 105 | F19: 14 | G19: =G18+0.55 -> 58.7 | H19: =H18+0.91 -> 96.74 | I19: =I18+2.43 -> 259.02 | J19: =J18+3.53 -> 376.42 | N19: =G19+G19+(G19*0.5) -> 146.75 | O19: =H19+H19+(H19*0.5) -> 241.85 | P19: =I19+I19+(I19*0.5) -> 647.55
C20: 15 | D20: 110 | F20: 15 | G20: =G19+0.55 -> 59.25 | H20: =H19+0.91 -> 97.65 | I20: =I19+2.43 -> 261.45 | J20: =J19+3.53 -> 379.95 | N20: =G20+G20+(G20*0.5) -> 148.125 | O20: =H20+H20+(H20*0.5) -> 244.125 | P20: =I20+I20+(I20*0.5) -> 653.625
C21: 16 | D21: 115 | F21: 16 | G21: =G20+0.55 -> 59.8 | H21: =H20+0.91 -> 98.56 | I21: =I20+2.43 -> 263.88 | J21: =J20+3.53 -> 383.48 | N21: =G21+G21+(G21*0.5) -> 149.5 | O21: =H21+H21+(H21*0.5) -> 246.4 | P21: =I21+I21+(I21*0.5) -> 659.7
C22: 17 | D22: 120 | F22: 17 | G22: =G21+0.55 -> 60.35 | H22: =H21+0.91 -> 99.47 | I22: =I21+2.43 -> 266.31 | J22: =J21+3.53 -> 387.01 | N22: =G22+G22+(G22*0.5) -> 150.875 | O22: =H22+H22+(H22*0.5) -> 248.675 | P22: =I22+I22+(I22*0.5) -> 665.775
C23: 18 | D23: 125 | F23: 18 | G23: =G22+0.55 -> 60.9 | H23: =H22+0.91 -> 100.38 | I23: =I22+2.43 -> 268.74 | J23: =J22+3.53 -> 390.54 | N23: =G23+G23+(G23*0.5) -> 152.25 | O23: =H23+H23+(H23*0.5) -> 250.95 | P23: =I23+I23+(I23*0.5) -> 671.85
